Watching for file changes with StatReloader
Watching for file changes with StatReloader
Internal Server Error: /
Traceback (most recent call last):
  File "/Users/malenkijkotik/Desktop/progs/rsoi/env/lib/python3.7/site-packages/django/core/handlers/exception.py", line 34, in inner
    response = get_response(request)
  File "/Users/malenkijkotik/Desktop/progs/rsoi/env/lib/python3.7/site-packages/django/core/handlers/base.py", line 115, in _get_response
    response = self.process_exception_by_middleware(e, request)
  File "/Users/malenkijkotik/Desktop/progs/rsoi/env/lib/python3.7/site-packages/django/core/handlers/base.py", line 113, in _get_response
    response = wrapped_callback(request, *callback_args, **callback_kwargs)
  File "/Users/malenkijkotik/Desktop/progs/rsoi/env/lib/python3.7/site-packages/django/views/decorators/csrf.py", line 54, in wrapped_view
    return view_func(*args, **kwargs)
  File "/Users/malenkijkotik/Desktop/progs/rsoi/env/lib/python3.7/site-packages/django/views/generic/base.py", line 71, in view
    return self.dispatch(request, *args, **kwargs)
  File "/Users/malenkijkotik/Desktop/progs/rsoi/env/lib/python3.7/site-packages/rest_framework/views.py", line 497, in dispatch
    response = self.handle_exception(exc)
  File "/Users/malenkijkotik/Desktop/progs/rsoi/env/lib/python3.7/site-packages/rest_framework/views.py", line 457, in handle_exception
    self.raise_uncaught_exception(exc)
  File "/Users/malenkijkotik/Desktop/progs/rsoi/env/lib/python3.7/site-packages/rest_framework/views.py", line 468, in raise_uncaught_exception
    raise exc
  File "/Users/malenkijkotik/Desktop/progs/rsoi/env/lib/python3.7/site-packages/rest_framework/views.py", line 494, in dispatch
    response = handler(request, *args, **kwargs)
TypeError: get() missing 1 required positional argument: 'uuid'
"GET / HTTP/1.1" 500 15045
/Users/malenkijkotik/Desktop/progs/rsoi-online-store/online-store-orders/orders_app/urls.py changed, reloading.
Watching for file changes with StatReloader
Internal Server Error: /
Traceback (most recent call last):
  File "/Users/malenkijkotik/Desktop/progs/rsoi/env/lib/python3.7/site-packages/django/core/handlers/exception.py", line 34, in inner
    response = get_response(request)
  File "/Users/malenkijkotik/Desktop/progs/rsoi/env/lib/python3.7/site-packages/django/core/handlers/base.py", line 115, in _get_response
    response = self.process_exception_by_middleware(e, request)
  File "/Users/malenkijkotik/Desktop/progs/rsoi/env/lib/python3.7/site-packages/django/core/handlers/base.py", line 113, in _get_response
    response = wrapped_callback(request, *callback_args, **callback_kwargs)
  File "/Users/malenkijkotik/Desktop/progs/rsoi/env/lib/python3.7/site-packages/django/views/decorators/csrf.py", line 54, in wrapped_view
    return view_func(*args, **kwargs)
  File "/Users/malenkijkotik/Desktop/progs/rsoi/env/lib/python3.7/site-packages/django/views/generic/base.py", line 71, in view
    return self.dispatch(request, *args, **kwargs)
  File "/Users/malenkijkotik/Desktop/progs/rsoi/env/lib/python3.7/site-packages/rest_framework/views.py", line 497, in dispatch
    response = self.handle_exception(exc)
  File "/Users/malenkijkotik/Desktop/progs/rsoi/env/lib/python3.7/site-packages/rest_framework/views.py", line 457, in handle_exception
    self.raise_uncaught_exception(exc)
  File "/Users/malenkijkotik/Desktop/progs/rsoi/env/lib/python3.7/site-packages/rest_framework/views.py", line 468, in raise_uncaught_exception
    raise exc
  File "/Users/malenkijkotik/Desktop/progs/rsoi/env/lib/python3.7/site-packages/rest_framework/views.py", line 494, in dispatch
    response = handler(request, *args, **kwargs)
  File "/Users/malenkijkotik/Desktop/progs/rsoi-online-store/online-store-orders/orders_app/views.py", line 34, in get
    order['billing'] = billing_response[0].json()
AttributeError: 'str' object has no attribute 'json'
"GET / HTTP/1.1" 500 15199
"GET / HTTP/1.1" 200 906
Watching for file changes with StatReloader
"GET / HTTP/1.1" 200 38
/Users/malenkijkotik/Desktop/progs/rsoi-online-store/online-store-orders/orders_app/views.py changed, reloading.
Watching for file changes with StatReloader
/Users/malenkijkotik/Desktop/progs/rsoi-online-store/online-store-orders/orders_app/views.py changed, reloading.
Watching for file changes with StatReloader
/Users/malenkijkotik/Desktop/progs/rsoi-online-store/online-store-orders/orders_app/views.py changed, reloading.
Watching for file changes with StatReloader
Internal Server Error: /
Traceback (most recent call last):
  File "/Users/malenkijkotik/Desktop/progs/rsoi/env/lib/python3.7/site-packages/django/core/handlers/exception.py", line 34, in inner
    response = get_response(request)
  File "/Users/malenkijkotik/Desktop/progs/rsoi/env/lib/python3.7/site-packages/django/core/handlers/base.py", line 115, in _get_response
    response = self.process_exception_by_middleware(e, request)
  File "/Users/malenkijkotik/Desktop/progs/rsoi/env/lib/python3.7/site-packages/django/core/handlers/base.py", line 113, in _get_response
    response = wrapped_callback(request, *callback_args, **callback_kwargs)
  File "/Users/malenkijkotik/Desktop/progs/rsoi/env/lib/python3.7/site-packages/django/views/decorators/csrf.py", line 54, in wrapped_view
    return view_func(*args, **kwargs)
  File "/Users/malenkijkotik/Desktop/progs/rsoi/env/lib/python3.7/site-packages/django/views/generic/base.py", line 71, in view
    return self.dispatch(request, *args, **kwargs)
  File "/Users/malenkijkotik/Desktop/progs/rsoi/env/lib/python3.7/site-packages/rest_framework/views.py", line 497, in dispatch
    response = self.handle_exception(exc)
  File "/Users/malenkijkotik/Desktop/progs/rsoi/env/lib/python3.7/site-packages/rest_framework/views.py", line 457, in handle_exception
    self.raise_uncaught_exception(exc)
  File "/Users/malenkijkotik/Desktop/progs/rsoi/env/lib/python3.7/site-packages/rest_framework/views.py", line 468, in raise_uncaught_exception
    raise exc
  File "/Users/malenkijkotik/Desktop/progs/rsoi/env/lib/python3.7/site-packages/rest_framework/views.py", line 494, in dispatch
    response = handler(request, *args, **kwargs)
  File "/Users/malenkijkotik/Desktop/progs/rsoi-online-store/online-store-orders/orders_app/views.py", line 37, in get
    order['billing'] = billing_response[0].json()
AttributeError: 'str' object has no attribute 'json'
"GET / HTTP/1.1" 500 15199
/Users/malenkijkotik/Desktop/progs/rsoi-online-store/online-store-orders/orders_app/views.py changed, reloading.
Watching for file changes with StatReloader
"GET / HTTP/1.1" 200 610
/Users/malenkijkotik/Desktop/progs/rsoi-online-store/online-store-orders/orders_app/views.py changed, reloading.
Watching for file changes with StatReloader
"GET / HTTP/1.1" 200 610
"GET /0152bdde-a2bb-48bd-87c1-cea7d78ac5af/ HTTP/1.1" 200 99
"GET / HTTP/1.1" 200 610
"GET /d9c78467-1948-4082-b1cc-2f7a693b40db/ HTTP/1.1" 200 208
Watching for file changes with StatReloader
Watching for file changes with StatReloader
"GET /d9c78467-1948-4082-b1cc-2f7a693b40db/ HTTP/1.1" 200 436
"GET / HTTP/1.1" 200 838
Watching for file changes with StatReloader
/Users/malenkijkotik/Desktop/progs/rsoi-online-store/online-store-orders/orders_app/urls.py changed, reloading.
Watching for file changes with StatReloader
Internal Server Error: /
Traceback (most recent call last):
  File "/Users/malenkijkotik/Desktop/progs/rsoi/env/lib/python3.7/site-packages/django/core/handlers/exception.py", line 34, in inner
    response = get_response(request)
  File "/Users/malenkijkotik/Desktop/progs/rsoi/env/lib/python3.7/site-packages/django/core/handlers/base.py", line 115, in _get_response
    response = self.process_exception_by_middleware(e, request)
  File "/Users/malenkijkotik/Desktop/progs/rsoi/env/lib/python3.7/site-packages/django/core/handlers/base.py", line 113, in _get_response
    response = wrapped_callback(request, *callback_args, **callback_kwargs)
  File "/Users/malenkijkotik/Desktop/progs/rsoi/env/lib/python3.7/site-packages/django/views/decorators/csrf.py", line 54, in wrapped_view
    return view_func(*args, **kwargs)
  File "/Users/malenkijkotik/Desktop/progs/rsoi/env/lib/python3.7/site-packages/django/views/generic/base.py", line 71, in view
    return self.dispatch(request, *args, **kwargs)
  File "/Users/malenkijkotik/Desktop/progs/rsoi/env/lib/python3.7/site-packages/rest_framework/views.py", line 497, in dispatch
    response = self.handle_exception(exc)
  File "/Users/malenkijkotik/Desktop/progs/rsoi/env/lib/python3.7/site-packages/rest_framework/views.py", line 457, in handle_exception
    self.raise_uncaught_exception(exc)
  File "/Users/malenkijkotik/Desktop/progs/rsoi/env/lib/python3.7/site-packages/rest_framework/views.py", line 468, in raise_uncaught_exception
    raise exc
  File "/Users/malenkijkotik/Desktop/progs/rsoi/env/lib/python3.7/site-packages/rest_framework/views.py", line 494, in dispatch
    response = handler(request, *args, **kwargs)
  File "/Users/malenkijkotik/Desktop/progs/rsoi-online-store/online-store-orders/orders_app/views.py", line 35, in get
    order['billing'] = billing_response[0].json()
  File "/Users/malenkijkotik/Desktop/progs/rsoi/env/lib/python3.7/site-packages/requests/models.py", line 897, in json
    return complexjson.loads(self.text, **kwargs)
  File "/Library/Frameworks/Python.framework/Versions/3.7/lib/python3.7/json/__init__.py", line 348, in loads
    return _default_decoder.decode(s)
  File "/Library/Frameworks/Python.framework/Versions/3.7/lib/python3.7/json/decoder.py", line 337, in decode
    obj, end = self.raw_decode(s, idx=_w(s, 0).end())
  File "/Library/Frameworks/Python.framework/Versions/3.7/lib/python3.7/json/decoder.py", line 355, in raw_decode
    raise JSONDecodeError("Expecting value", s, err.value) from None
json.decoder.JSONDecodeError: Expecting value: line 1 column 1 (char 0)
"GET / HTTP/1.1" 500 16107
/Users/malenkijkotik/Desktop/progs/rsoi-online-store/online-store-orders/orders_app/urls.py changed, reloading.
Watching for file changes with StatReloader
Internal Server Error: /
Traceback (most recent call last):
  File "/Users/malenkijkotik/Desktop/progs/rsoi/env/lib/python3.7/site-packages/django/core/handlers/exception.py", line 34, in inner
    response = get_response(request)
  File "/Users/malenkijkotik/Desktop/progs/rsoi/env/lib/python3.7/site-packages/django/core/handlers/base.py", line 115, in _get_response
    response = self.process_exception_by_middleware(e, request)
  File "/Users/malenkijkotik/Desktop/progs/rsoi/env/lib/python3.7/site-packages/django/core/handlers/base.py", line 113, in _get_response
    response = wrapped_callback(request, *callback_args, **callback_kwargs)
  File "/Users/malenkijkotik/Desktop/progs/rsoi/env/lib/python3.7/site-packages/django/views/decorators/csrf.py", line 54, in wrapped_view
    return view_func(*args, **kwargs)
  File "/Users/malenkijkotik/Desktop/progs/rsoi/env/lib/python3.7/site-packages/django/views/generic/base.py", line 71, in view
    return self.dispatch(request, *args, **kwargs)
  File "/Users/malenkijkotik/Desktop/progs/rsoi/env/lib/python3.7/site-packages/rest_framework/views.py", line 497, in dispatch
    response = self.handle_exception(exc)
  File "/Users/malenkijkotik/Desktop/progs/rsoi/env/lib/python3.7/site-packages/rest_framework/views.py", line 457, in handle_exception
    self.raise_uncaught_exception(exc)
  File "/Users/malenkijkotik/Desktop/progs/rsoi/env/lib/python3.7/site-packages/rest_framework/views.py", line 468, in raise_uncaught_exception
    raise exc
  File "/Users/malenkijkotik/Desktop/progs/rsoi/env/lib/python3.7/site-packages/rest_framework/views.py", line 494, in dispatch
    response = handler(request, *args, **kwargs)
  File "/Users/malenkijkotik/Desktop/progs/rsoi-online-store/online-store-orders/orders_app/views.py", line 35, in get
    order['billing'] = billing_response[0].json()
  File "/Users/malenkijkotik/Desktop/progs/rsoi/env/lib/python3.7/site-packages/requests/models.py", line 897, in json
    return complexjson.loads(self.text, **kwargs)
  File "/Library/Frameworks/Python.framework/Versions/3.7/lib/python3.7/json/__init__.py", line 348, in loads
    return _default_decoder.decode(s)
  File "/Library/Frameworks/Python.framework/Versions/3.7/lib/python3.7/json/decoder.py", line 337, in decode
    obj, end = self.raw_decode(s, idx=_w(s, 0).end())
  File "/Library/Frameworks/Python.framework/Versions/3.7/lib/python3.7/json/decoder.py", line 355, in raw_decode
    raise JSONDecodeError("Expecting value", s, err.value) from None
json.decoder.JSONDecodeError: Expecting value: line 1 column 1 (char 0)
"GET / HTTP/1.1" 500 16107
/Users/malenkijkotik/Desktop/progs/rsoi-online-store/online-store-orders/orders_app/views.py changed, reloading.
Watching for file changes with StatReloader
Internal Server Error: /
Traceback (most recent call last):
  File "/Users/malenkijkotik/Desktop/progs/rsoi/env/lib/python3.7/site-packages/django/core/handlers/exception.py", line 34, in inner
    response = get_response(request)
  File "/Users/malenkijkotik/Desktop/progs/rsoi/env/lib/python3.7/site-packages/django/core/handlers/base.py", line 115, in _get_response
    response = self.process_exception_by_middleware(e, request)
  File "/Users/malenkijkotik/Desktop/progs/rsoi/env/lib/python3.7/site-packages/django/core/handlers/base.py", line 113, in _get_response
    response = wrapped_callback(request, *callback_args, **callback_kwargs)
  File "/Users/malenkijkotik/Desktop/progs/rsoi/env/lib/python3.7/site-packages/django/views/decorators/csrf.py", line 54, in wrapped_view
    return view_func(*args, **kwargs)
  File "/Users/malenkijkotik/Desktop/progs/rsoi/env/lib/python3.7/site-packages/django/views/generic/base.py", line 71, in view
    return self.dispatch(request, *args, **kwargs)
  File "/Users/malenkijkotik/Desktop/progs/rsoi/env/lib/python3.7/site-packages/rest_framework/views.py", line 497, in dispatch
    response = self.handle_exception(exc)
  File "/Users/malenkijkotik/Desktop/progs/rsoi/env/lib/python3.7/site-packages/rest_framework/views.py", line 457, in handle_exception
    self.raise_uncaught_exception(exc)
  File "/Users/malenkijkotik/Desktop/progs/rsoi/env/lib/python3.7/site-packages/rest_framework/views.py", line 468, in raise_uncaught_exception
    raise exc
  File "/Users/malenkijkotik/Desktop/progs/rsoi/env/lib/python3.7/site-packages/rest_framework/views.py", line 494, in dispatch
    response = handler(request, *args, **kwargs)
  File "/Users/malenkijkotik/Desktop/progs/rsoi-online-store/online-store-orders/orders_app/views.py", line 36, in get
    order['billing'] = billing_response[0].json()
  File "/Users/malenkijkotik/Desktop/progs/rsoi/env/lib/python3.7/site-packages/requests/models.py", line 897, in json
    return complexjson.loads(self.text, **kwargs)
  File "/Library/Frameworks/Python.framework/Versions/3.7/lib/python3.7/json/__init__.py", line 348, in loads
    return _default_decoder.decode(s)
  File "/Library/Frameworks/Python.framework/Versions/3.7/lib/python3.7/json/decoder.py", line 337, in decode
    obj, end = self.raw_decode(s, idx=_w(s, 0).end())
  File "/Library/Frameworks/Python.framework/Versions/3.7/lib/python3.7/json/decoder.py", line 355, in raw_decode
    raise JSONDecodeError("Expecting value", s, err.value) from None
json.decoder.JSONDecodeError: Expecting value: line 1 column 1 (char 0)
"GET / HTTP/1.1" 500 16107
/Users/malenkijkotik/Desktop/progs/rsoi-online-store/online-store-orders/orders_app/views.py changed, reloading.
Watching for file changes with StatReloader
Internal Server Error: /
Traceback (most recent call last):
  File "/Users/malenkijkotik/Desktop/progs/rsoi/env/lib/python3.7/site-packages/django/core/handlers/exception.py", line 34, in inner
    response = get_response(request)
  File "/Users/malenkijkotik/Desktop/progs/rsoi/env/lib/python3.7/site-packages/django/core/handlers/base.py", line 115, in _get_response
    response = self.process_exception_by_middleware(e, request)
  File "/Users/malenkijkotik/Desktop/progs/rsoi/env/lib/python3.7/site-packages/django/core/handlers/base.py", line 113, in _get_response
    response = wrapped_callback(request, *callback_args, **callback_kwargs)
  File "/Users/malenkijkotik/Desktop/progs/rsoi/env/lib/python3.7/site-packages/django/views/decorators/csrf.py", line 54, in wrapped_view
    return view_func(*args, **kwargs)
  File "/Users/malenkijkotik/Desktop/progs/rsoi/env/lib/python3.7/site-packages/django/views/generic/base.py", line 71, in view
    return self.dispatch(request, *args, **kwargs)
  File "/Users/malenkijkotik/Desktop/progs/rsoi/env/lib/python3.7/site-packages/rest_framework/views.py", line 497, in dispatch
    response = self.handle_exception(exc)
  File "/Users/malenkijkotik/Desktop/progs/rsoi/env/lib/python3.7/site-packages/rest_framework/views.py", line 457, in handle_exception
    self.raise_uncaught_exception(exc)
  File "/Users/malenkijkotik/Desktop/progs/rsoi/env/lib/python3.7/site-packages/rest_framework/views.py", line 468, in raise_uncaught_exception
    raise exc
  File "/Users/malenkijkotik/Desktop/progs/rsoi/env/lib/python3.7/site-packages/rest_framework/views.py", line 494, in dispatch
    response = handler(request, *args, **kwargs)
  File "/Users/malenkijkotik/Desktop/progs/rsoi-online-store/online-store-orders/orders_app/views.py", line 37, in get
    order['billing'] = billing_response[0].json()
  File "/Users/malenkijkotik/Desktop/progs/rsoi/env/lib/python3.7/site-packages/requests/models.py", line 897, in json
    return complexjson.loads(self.text, **kwargs)
  File "/Library/Frameworks/Python.framework/Versions/3.7/lib/python3.7/json/__init__.py", line 348, in loads
    return _default_decoder.decode(s)
  File "/Library/Frameworks/Python.framework/Versions/3.7/lib/python3.7/json/decoder.py", line 337, in decode
    obj, end = self.raw_decode(s, idx=_w(s, 0).end())
  File "/Library/Frameworks/Python.framework/Versions/3.7/lib/python3.7/json/decoder.py", line 355, in raw_decode
    raise JSONDecodeError("Expecting value", s, err.value) from None
json.decoder.JSONDecodeError: Expecting value: line 1 column 1 (char 0)
"GET / HTTP/1.1" 500 16107
/Users/malenkijkotik/Desktop/progs/rsoi-online-store/online-store-orders/orders_app/requesters/billing_requester.py changed, reloading.
Watching for file changes with StatReloader
/Users/malenkijkotik/Desktop/progs/rsoi-online-store/online-store-orders/orders_app/requesters/items_requester.py changed, reloading.
Watching for file changes with StatReloader
"GET / HTTP/1.1" 200 838
"GET /orders_short/ HTTP/1.1" 200 610
"GET / HTTP/1.1" 200 838
"GET /orders_short/ HTTP/1.1" 200 610
"GET /orders_short/d9c78467-1948-4082-b1cc-2f7a693b40db/ HTTP/1.1" 200 436
/Users/malenkijkotik/Desktop/progs/rsoi-online-store/online-store-orders/orders_app/views.py changed, reloading.
Watching for file changes with StatReloader
/Users/malenkijkotik/Desktop/progs/rsoi-online-store/online-store-orders/orders_app/views.py changed, reloading.
Watching for file changes with StatReloader
Internal Server Error: /orders_short/d9c78467-1948-4082-b1cc-2f7a693b40db/
Traceback (most recent call last):
  File "/Users/malenkijkotik/Desktop/progs/rsoi/env/lib/python3.7/site-packages/django/core/handlers/exception.py", line 34, in inner
    response = get_response(request)
  File "/Users/malenkijkotik/Desktop/progs/rsoi/env/lib/python3.7/site-packages/django/core/handlers/base.py", line 115, in _get_response
    response = self.process_exception_by_middleware(e, request)
  File "/Users/malenkijkotik/Desktop/progs/rsoi/env/lib/python3.7/site-packages/django/core/handlers/base.py", line 113, in _get_response
    response = wrapped_callback(request, *callback_args, **callback_kwargs)
  File "/Users/malenkijkotik/Desktop/progs/rsoi/env/lib/python3.7/site-packages/django/views/decorators/csrf.py", line 54, in wrapped_view
    return view_func(*args, **kwargs)
  File "/Users/malenkijkotik/Desktop/progs/rsoi/env/lib/python3.7/site-packages/django/views/generic/base.py", line 71, in view
    return self.dispatch(request, *args, **kwargs)
  File "/Users/malenkijkotik/Desktop/progs/rsoi/env/lib/python3.7/site-packages/rest_framework/views.py", line 497, in dispatch
    response = self.handle_exception(exc)
  File "/Users/malenkijkotik/Desktop/progs/rsoi/env/lib/python3.7/site-packages/rest_framework/views.py", line 457, in handle_exception
    self.raise_uncaught_exception(exc)
  File "/Users/malenkijkotik/Desktop/progs/rsoi/env/lib/python3.7/site-packages/rest_framework/views.py", line 468, in raise_uncaught_exception
    raise exc
  File "/Users/malenkijkotik/Desktop/progs/rsoi/env/lib/python3.7/site-packages/rest_framework/views.py", line 494, in dispatch
    response = handler(request, *args, **kwargs)
  File "/Users/malenkijkotik/Desktop/progs/rsoi-online-store/online-store-orders/orders_app/views.py", line 128, in get
    return Response(serialized, status=status.HTTP_200_OK)
  File "/Users/malenkijkotik/Desktop/progs/rsoi/env/lib/python3.7/site-packages/rest_framework/response.py", line 38, in __init__
    raise AssertionError(msg)
AssertionError: You passed a Serializer instance as data, but probably meant to pass serialized `.data` or `.error`. representation.
"GET /orders_short/d9c78467-1948-4082-b1cc-2f7a693b40db/ HTTP/1.1" 500 15724
/Users/malenkijkotik/Desktop/progs/rsoi-online-store/online-store-orders/orders_app/views.py changed, reloading.
Watching for file changes with StatReloader
"GET /orders_short/d9c78467-1948-4082-b1cc-2f7a693b40db/ HTTP/1.1" 200 208
/Users/malenkijkotik/Desktop/progs/rsoi-online-store/online-store-orders/orders_app/views.py changed, reloading.
Watching for file changes with StatReloader
/Users/malenkijkotik/Desktop/progs/rsoi-online-store/online-store-orders/orders_app/requesters/items_requester.py changed, reloading.
Watching for file changes with StatReloader
Watching for file changes with StatReloader
/Users/malenkijkotik/Desktop/progs/rsoi-online-store/online-store-orders/orders_app/requesters/billing_requester.py changed, reloading.
Watching for file changes with StatReloader
Internal Server Error: /
"POST / HTTP/1.1" 500 0
Internal Server Error: /
Traceback (most recent call last):
  File "/Users/malenkijkotik/Desktop/progs/rsoi/env/lib/python3.7/site-packages/django/core/handlers/exception.py", line 34, in inner
    response = get_response(request)
  File "/Users/malenkijkotik/Desktop/progs/rsoi/env/lib/python3.7/site-packages/django/core/handlers/base.py", line 115, in _get_response
    response = self.process_exception_by_middleware(e, request)
  File "/Users/malenkijkotik/Desktop/progs/rsoi/env/lib/python3.7/site-packages/django/core/handlers/base.py", line 113, in _get_response
    response = wrapped_callback(request, *callback_args, **callback_kwargs)
  File "/Users/malenkijkotik/Desktop/progs/rsoi/env/lib/python3.7/site-packages/django/views/decorators/csrf.py", line 54, in wrapped_view
    return view_func(*args, **kwargs)
  File "/Users/malenkijkotik/Desktop/progs/rsoi/env/lib/python3.7/site-packages/django/views/generic/base.py", line 71, in view
    return self.dispatch(request, *args, **kwargs)
  File "/Users/malenkijkotik/Desktop/progs/rsoi/env/lib/python3.7/site-packages/rest_framework/views.py", line 497, in dispatch
    response = self.handle_exception(exc)
  File "/Users/malenkijkotik/Desktop/progs/rsoi/env/lib/python3.7/site-packages/rest_framework/views.py", line 457, in handle_exception
    self.raise_uncaught_exception(exc)
  File "/Users/malenkijkotik/Desktop/progs/rsoi/env/lib/python3.7/site-packages/rest_framework/views.py", line 468, in raise_uncaught_exception
    raise exc
  File "/Users/malenkijkotik/Desktop/progs/rsoi/env/lib/python3.7/site-packages/rest_framework/views.py", line 494, in dispatch
    response = handler(request, *args, **kwargs)
  File "/Users/malenkijkotik/Desktop/progs/rsoi-online-store/online-store-orders/orders_app/views.py", line 54, in post
    serializer = OrderSerializer(data=data, billing=billing_uuid)
  File "/Users/malenkijkotik/Desktop/progs/rsoi/env/lib/python3.7/site-packages/rest_framework/serializers.py", line 117, in __init__
    super().__init__(**kwargs)
TypeError: __init__() got an unexpected keyword argument 'billing'
"POST / HTTP/1.1" 500 15441
/Users/malenkijkotik/Desktop/progs/rsoi-online-store/online-store-orders/orders_app/views.py changed, reloading.
Watching for file changes with StatReloader
/Users/malenkijkotik/Desktop/progs/rsoi-online-store/online-store-orders/orders_app/views.py changed, reloading.
Watching for file changes with StatReloader
Internal Server Error: /
Traceback (most recent call last):
  File "/Users/malenkijkotik/Desktop/progs/rsoi/env/lib/python3.7/site-packages/django/core/handlers/exception.py", line 34, in inner
    response = get_response(request)
  File "/Users/malenkijkotik/Desktop/progs/rsoi/env/lib/python3.7/site-packages/django/core/handlers/base.py", line 115, in _get_response
    response = self.process_exception_by_middleware(e, request)
  File "/Users/malenkijkotik/Desktop/progs/rsoi/env/lib/python3.7/site-packages/django/core/handlers/base.py", line 113, in _get_response
    response = wrapped_callback(request, *callback_args, **callback_kwargs)
  File "/Users/malenkijkotik/Desktop/progs/rsoi/env/lib/python3.7/site-packages/django/views/decorators/csrf.py", line 54, in wrapped_view
    return view_func(*args, **kwargs)
  File "/Users/malenkijkotik/Desktop/progs/rsoi/env/lib/python3.7/site-packages/django/views/generic/base.py", line 71, in view
    return self.dispatch(request, *args, **kwargs)
  File "/Users/malenkijkotik/Desktop/progs/rsoi/env/lib/python3.7/site-packages/rest_framework/views.py", line 497, in dispatch
    response = self.handle_exception(exc)
  File "/Users/malenkijkotik/Desktop/progs/rsoi/env/lib/python3.7/site-packages/rest_framework/views.py", line 457, in handle_exception
    self.raise_uncaught_exception(exc)
  File "/Users/malenkijkotik/Desktop/progs/rsoi/env/lib/python3.7/site-packages/rest_framework/views.py", line 468, in raise_uncaught_exception
    raise exc
  File "/Users/malenkijkotik/Desktop/progs/rsoi/env/lib/python3.7/site-packages/rest_framework/views.py", line 494, in dispatch
    response = handler(request, *args, **kwargs)
  File "/Users/malenkijkotik/Desktop/progs/rsoi-online-store/online-store-orders/orders_app/views.py", line 54, in post
    serializer = OrderSerializer(isClosed=data.isClosed, itemsInOrder=data.itemsInOrder, billing=billing_uuid)
AttributeError: 'QueryDict' object has no attribute 'isClosed'
"POST / HTTP/1.1" 500 15314
/Users/malenkijkotik/Desktop/progs/rsoi-online-store/online-store-orders/orders_app/views.py changed, reloading.
Watching for file changes with StatReloader
/Users/malenkijkotik/Desktop/progs/rsoi-online-store/online-store-orders/orders_app/views.py changed, reloading.
Watching for file changes with StatReloader
Internal Server Error: /
Traceback (most recent call last):
  File "/Users/malenkijkotik/Desktop/progs/rsoi-online-store/online-store-orders/orders_app/requesters/requester.py", line 48, in get_data_from_response
    return response.json()
AttributeError: 'QueryDict' object has no attribute 'json'

During handling of the above exception, another exception occurred:

Traceback (most recent call last):
  File "/Users/malenkijkotik/Desktop/progs/rsoi/env/lib/python3.7/site-packages/django/core/handlers/exception.py", line 34, in inner
    response = get_response(request)
  File "/Users/malenkijkotik/Desktop/progs/rsoi/env/lib/python3.7/site-packages/django/core/handlers/base.py", line 115, in _get_response
    response = self.process_exception_by_middleware(e, request)
  File "/Users/malenkijkotik/Desktop/progs/rsoi/env/lib/python3.7/site-packages/django/core/handlers/base.py", line 113, in _get_response
    response = wrapped_callback(request, *callback_args, **callback_kwargs)
  File "/Users/malenkijkotik/Desktop/progs/rsoi/env/lib/python3.7/site-packages/django/views/decorators/csrf.py", line 54, in wrapped_view
    return view_func(*args, **kwargs)
  File "/Users/malenkijkotik/Desktop/progs/rsoi/env/lib/python3.7/site-packages/django/views/generic/base.py", line 71, in view
    return self.dispatch(request, *args, **kwargs)
  File "/Users/malenkijkotik/Desktop/progs/rsoi/env/lib/python3.7/site-packages/rest_framework/views.py", line 497, in dispatch
    response = self.handle_exception(exc)
  File "/Users/malenkijkotik/Desktop/progs/rsoi/env/lib/python3.7/site-packages/rest_framework/views.py", line 457, in handle_exception
    self.raise_uncaught_exception(exc)
  File "/Users/malenkijkotik/Desktop/progs/rsoi/env/lib/python3.7/site-packages/rest_framework/views.py", line 468, in raise_uncaught_exception
    raise exc
  File "/Users/malenkijkotik/Desktop/progs/rsoi/env/lib/python3.7/site-packages/rest_framework/views.py", line 494, in dispatch
    response = handler(request, *args, **kwargs)
  File "/Users/malenkijkotik/Desktop/progs/rsoi-online-store/online-store-orders/orders_app/views.py", line 49, in post
    data = self.BILLING_REQUESTER.get_data_from_response(data)
  File "/Users/malenkijkotik/Desktop/progs/rsoi-online-store/online-store-orders/orders_app/requesters/requester.py", line 50, in get_data_from_response
    return response.text
AttributeError: 'QueryDict' object has no attribute 'text'
"POST / HTTP/1.1" 500 15718
/Users/malenkijkotik/Desktop/progs/rsoi-online-store/online-store-orders/orders_app/views.py changed, reloading.
Watching for file changes with StatReloader
Internal Server Error: /
Traceback (most recent call last):
  File "/Users/malenkijkotik/Desktop/progs/rsoi/env/lib/python3.7/site-packages/django/core/handlers/exception.py", line 34, in inner
    response = get_response(request)
  File "/Users/malenkijkotik/Desktop/progs/rsoi/env/lib/python3.7/site-packages/django/core/handlers/base.py", line 115, in _get_response
    response = self.process_exception_by_middleware(e, request)
  File "/Users/malenkijkotik/Desktop/progs/rsoi/env/lib/python3.7/site-packages/django/core/handlers/base.py", line 113, in _get_response
    response = wrapped_callback(request, *callback_args, **callback_kwargs)
  File "/Users/malenkijkotik/Desktop/progs/rsoi/env/lib/python3.7/site-packages/django/views/decorators/csrf.py", line 54, in wrapped_view
    return view_func(*args, **kwargs)
  File "/Users/malenkijkotik/Desktop/progs/rsoi/env/lib/python3.7/site-packages/django/views/generic/base.py", line 71, in view
    return self.dispatch(request, *args, **kwargs)
  File "/Users/malenkijkotik/Desktop/progs/rsoi/env/lib/python3.7/site-packages/rest_framework/views.py", line 497, in dispatch
    response = self.handle_exception(exc)
  File "/Users/malenkijkotik/Desktop/progs/rsoi/env/lib/python3.7/site-packages/rest_framework/views.py", line 457, in handle_exception
    self.raise_uncaught_exception(exc)
  File "/Users/malenkijkotik/Desktop/progs/rsoi/env/lib/python3.7/site-packages/rest_framework/views.py", line 468, in raise_uncaught_exception
    raise exc
  File "/Users/malenkijkotik/Desktop/progs/rsoi/env/lib/python3.7/site-packages/rest_framework/views.py", line 494, in dispatch
    response = handler(request, *args, **kwargs)
  File "/Users/malenkijkotik/Desktop/progs/rsoi-online-store/online-store-orders/orders_app/views.py", line 54, in post
    serializer = OrderSerializer(billing=billing_uuid)
  File "/Users/malenkijkotik/Desktop/progs/rsoi/env/lib/python3.7/site-packages/rest_framework/serializers.py", line 117, in __init__
    super().__init__(**kwargs)
TypeError: __init__() got an unexpected keyword argument 'billing'
"POST / HTTP/1.1" 500 15430
/Users/malenkijkotik/Desktop/progs/rsoi-online-store/online-store-orders/orders_app/views.py changed, reloading.
Watching for file changes with StatReloader
/Users/malenkijkotik/Desktop/progs/rsoi-online-store/online-store-orders/orders_app/views.py changed, reloading.
Watching for file changes with StatReloader
Internal Server Error: /
Traceback (most recent call last):
  File "/Users/malenkijkotik/Desktop/progs/rsoi/env/lib/python3.7/site-packages/django/core/handlers/exception.py", line 34, in inner
    response = get_response(request)
  File "/Users/malenkijkotik/Desktop/progs/rsoi/env/lib/python3.7/site-packages/django/core/handlers/base.py", line 115, in _get_response
    response = self.process_exception_by_middleware(e, request)
  File "/Users/malenkijkotik/Desktop/progs/rsoi/env/lib/python3.7/site-packages/django/core/handlers/base.py", line 113, in _get_response
    response = wrapped_callback(request, *callback_args, **callback_kwargs)
  File "/Users/malenkijkotik/Desktop/progs/rsoi/env/lib/python3.7/site-packages/django/views/decorators/csrf.py", line 54, in wrapped_view
    return view_func(*args, **kwargs)
  File "/Users/malenkijkotik/Desktop/progs/rsoi/env/lib/python3.7/site-packages/django/views/generic/base.py", line 71, in view
    return self.dispatch(request, *args, **kwargs)
  File "/Users/malenkijkotik/Desktop/progs/rsoi/env/lib/python3.7/site-packages/rest_framework/views.py", line 497, in dispatch
    response = self.handle_exception(exc)
  File "/Users/malenkijkotik/Desktop/progs/rsoi/env/lib/python3.7/site-packages/rest_framework/views.py", line 457, in handle_exception
    self.raise_uncaught_exception(exc)
  File "/Users/malenkijkotik/Desktop/progs/rsoi/env/lib/python3.7/site-packages/rest_framework/views.py", line 468, in raise_uncaught_exception
    raise exc
  File "/Users/malenkijkotik/Desktop/progs/rsoi/env/lib/python3.7/site-packages/rest_framework/views.py", line 494, in dispatch
    response = handler(request, *args, **kwargs)
  File "/Users/malenkijkotik/Desktop/progs/rsoi-online-store/online-store-orders/orders_app/views.py", line 56, in post
    if serializer.is_valid():
AttributeError: 'ReturnDict' object has no attribute 'is_valid'
"POST / HTTP/1.1" 500 15235
/Users/malenkijkotik/Desktop/progs/rsoi-online-store/online-store-orders/orders_app/views.py changed, reloading.
Watching for file changes with StatReloader
Internal Server Error: /
Traceback (most recent call last):
  File "/Users/malenkijkotik/Desktop/progs/rsoi/env/lib/python3.7/site-packages/django/core/handlers/exception.py", line 34, in inner
    response = get_response(request)
  File "/Users/malenkijkotik/Desktop/progs/rsoi/env/lib/python3.7/site-packages/django/core/handlers/base.py", line 115, in _get_response
    response = self.process_exception_by_middleware(e, request)
  File "/Users/malenkijkotik/Desktop/progs/rsoi/env/lib/python3.7/site-packages/django/core/handlers/base.py", line 113, in _get_response
    response = wrapped_callback(request, *callback_args, **callback_kwargs)
  File "/Users/malenkijkotik/Desktop/progs/rsoi/env/lib/python3.7/site-packages/django/views/decorators/csrf.py", line 54, in wrapped_view
    return view_func(*args, **kwargs)
  File "/Users/malenkijkotik/Desktop/progs/rsoi/env/lib/python3.7/site-packages/django/views/generic/base.py", line 71, in view
    return self.dispatch(request, *args, **kwargs)
  File "/Users/malenkijkotik/Desktop/progs/rsoi/env/lib/python3.7/site-packages/rest_framework/views.py", line 497, in dispatch
    response = self.handle_exception(exc)
  File "/Users/malenkijkotik/Desktop/progs/rsoi/env/lib/python3.7/site-packages/rest_framework/views.py", line 457, in handle_exception
    self.raise_uncaught_exception(exc)
  File "/Users/malenkijkotik/Desktop/progs/rsoi/env/lib/python3.7/site-packages/rest_framework/views.py", line 468, in raise_uncaught_exception
    raise exc
  File "/Users/malenkijkotik/Desktop/progs/rsoi/env/lib/python3.7/site-packages/rest_framework/views.py", line 494, in dispatch
    response = handler(request, *args, **kwargs)
  File "/Users/malenkijkotik/Desktop/progs/rsoi-online-store/online-store-orders/orders_app/views.py", line 56, in post
    serializer.save()
AttributeError: 'ReturnDict' object has no attribute 'save'
"POST / HTTP/1.1" 500 15219
/Users/malenkijkotik/Desktop/progs/rsoi-online-store/online-store-orders/orders_app/views.py changed, reloading.
Watching for file changes with StatReloader
"POST / HTTP/1.1" 201 133
"POST / HTTP/1.1" 201 133
"POST / HTTP/1.1" 201 133
