Watching for file changes with StatReloader
Watching for file changes with StatReloader
Internal Server Error: /
Traceback (most recent call last):
  File "/Users/malenkijkotik/Desktop/progs/rsoi/env/lib/python3.7/site-packages/django/core/handlers/exception.py", line 34, in inner
    response = get_response(request)
  File "/Users/malenkijkotik/Desktop/progs/rsoi/env/lib/python3.7/site-packages/django/core/handlers/base.py", line 115, in _get_response
    response = self.process_exception_by_middleware(e, request)
  File "/Users/malenkijkotik/Desktop/progs/rsoi/env/lib/python3.7/site-packages/django/core/handlers/base.py", line 113, in _get_response
    response = wrapped_callback(request, *callback_args, **callback_kwargs)
  File "/Users/malenkijkotik/Desktop/progs/rsoi/env/lib/python3.7/site-packages/django/views/decorators/csrf.py", line 54, in wrapped_view
    return view_func(*args, **kwargs)
  File "/Users/malenkijkotik/Desktop/progs/rsoi/env/lib/python3.7/site-packages/django/views/generic/base.py", line 71, in view
    return self.dispatch(request, *args, **kwargs)
  File "/Users/malenkijkotik/Desktop/progs/rsoi/env/lib/python3.7/site-packages/rest_framework/views.py", line 497, in dispatch
    response = self.handle_exception(exc)
  File "/Users/malenkijkotik/Desktop/progs/rsoi/env/lib/python3.7/site-packages/rest_framework/views.py", line 457, in handle_exception
    self.raise_uncaught_exception(exc)
  File "/Users/malenkijkotik/Desktop/progs/rsoi/env/lib/python3.7/site-packages/rest_framework/views.py", line 468, in raise_uncaught_exception
    raise exc
  File "/Users/malenkijkotik/Desktop/progs/rsoi/env/lib/python3.7/site-packages/rest_framework/views.py", line 494, in dispatch
    response = handler(request, *args, **kwargs)
TypeError: get() missing 1 required positional argument: 'uuid'
"GET / HTTP/1.1" 500 15045
/Users/malenkijkotik/Desktop/progs/rsoi-online-store/online-store-orders/orders_app/urls.py changed, reloading.
Watching for file changes with StatReloader
Internal Server Error: /
Traceback (most recent call last):
  File "/Users/malenkijkotik/Desktop/progs/rsoi/env/lib/python3.7/site-packages/django/core/handlers/exception.py", line 34, in inner
    response = get_response(request)
  File "/Users/malenkijkotik/Desktop/progs/rsoi/env/lib/python3.7/site-packages/django/core/handlers/base.py", line 115, in _get_response
    response = self.process_exception_by_middleware(e, request)
  File "/Users/malenkijkotik/Desktop/progs/rsoi/env/lib/python3.7/site-packages/django/core/handlers/base.py", line 113, in _get_response
    response = wrapped_callback(request, *callback_args, **callback_kwargs)
  File "/Users/malenkijkotik/Desktop/progs/rsoi/env/lib/python3.7/site-packages/django/views/decorators/csrf.py", line 54, in wrapped_view
    return view_func(*args, **kwargs)
  File "/Users/malenkijkotik/Desktop/progs/rsoi/env/lib/python3.7/site-packages/django/views/generic/base.py", line 71, in view
    return self.dispatch(request, *args, **kwargs)
  File "/Users/malenkijkotik/Desktop/progs/rsoi/env/lib/python3.7/site-packages/rest_framework/views.py", line 497, in dispatch
    response = self.handle_exception(exc)
  File "/Users/malenkijkotik/Desktop/progs/rsoi/env/lib/python3.7/site-packages/rest_framework/views.py", line 457, in handle_exception
    self.raise_uncaught_exception(exc)
  File "/Users/malenkijkotik/Desktop/progs/rsoi/env/lib/python3.7/site-packages/rest_framework/views.py", line 468, in raise_uncaught_exception
    raise exc
  File "/Users/malenkijkotik/Desktop/progs/rsoi/env/lib/python3.7/site-packages/rest_framework/views.py", line 494, in dispatch
    response = handler(request, *args, **kwargs)
  File "/Users/malenkijkotik/Desktop/progs/rsoi-online-store/online-store-orders/orders_app/views.py", line 34, in get
    order['billing'] = billing_response[0].json()
AttributeError: 'str' object has no attribute 'json'
"GET / HTTP/1.1" 500 15199
"GET / HTTP/1.1" 200 906
Watching for file changes with StatReloader
"GET / HTTP/1.1" 200 38
/Users/malenkijkotik/Desktop/progs/rsoi-online-store/online-store-orders/orders_app/views.py changed, reloading.
Watching for file changes with StatReloader
/Users/malenkijkotik/Desktop/progs/rsoi-online-store/online-store-orders/orders_app/views.py changed, reloading.
Watching for file changes with StatReloader
/Users/malenkijkotik/Desktop/progs/rsoi-online-store/online-store-orders/orders_app/views.py changed, reloading.
Watching for file changes with StatReloader
Internal Server Error: /
Traceback (most recent call last):
  File "/Users/malenkijkotik/Desktop/progs/rsoi/env/lib/python3.7/site-packages/django/core/handlers/exception.py", line 34, in inner
    response = get_response(request)
  File "/Users/malenkijkotik/Desktop/progs/rsoi/env/lib/python3.7/site-packages/django/core/handlers/base.py", line 115, in _get_response
    response = self.process_exception_by_middleware(e, request)
  File "/Users/malenkijkotik/Desktop/progs/rsoi/env/lib/python3.7/site-packages/django/core/handlers/base.py", line 113, in _get_response
    response = wrapped_callback(request, *callback_args, **callback_kwargs)
  File "/Users/malenkijkotik/Desktop/progs/rsoi/env/lib/python3.7/site-packages/django/views/decorators/csrf.py", line 54, in wrapped_view
    return view_func(*args, **kwargs)
  File "/Users/malenkijkotik/Desktop/progs/rsoi/env/lib/python3.7/site-packages/django/views/generic/base.py", line 71, in view
    return self.dispatch(request, *args, **kwargs)
  File "/Users/malenkijkotik/Desktop/progs/rsoi/env/lib/python3.7/site-packages/rest_framework/views.py", line 497, in dispatch
    response = self.handle_exception(exc)
  File "/Users/malenkijkotik/Desktop/progs/rsoi/env/lib/python3.7/site-packages/rest_framework/views.py", line 457, in handle_exception
    self.raise_uncaught_exception(exc)
  File "/Users/malenkijkotik/Desktop/progs/rsoi/env/lib/python3.7/site-packages/rest_framework/views.py", line 468, in raise_uncaught_exception
    raise exc
  File "/Users/malenkijkotik/Desktop/progs/rsoi/env/lib/python3.7/site-packages/rest_framework/views.py", line 494, in dispatch
    response = handler(request, *args, **kwargs)
  File "/Users/malenkijkotik/Desktop/progs/rsoi-online-store/online-store-orders/orders_app/views.py", line 37, in get
    order['billing'] = billing_response[0].json()
AttributeError: 'str' object has no attribute 'json'
"GET / HTTP/1.1" 500 15199
/Users/malenkijkotik/Desktop/progs/rsoi-online-store/online-store-orders/orders_app/views.py changed, reloading.
Watching for file changes with StatReloader
"GET / HTTP/1.1" 200 610
/Users/malenkijkotik/Desktop/progs/rsoi-online-store/online-store-orders/orders_app/views.py changed, reloading.
Watching for file changes with StatReloader
"GET / HTTP/1.1" 200 610
"GET /0152bdde-a2bb-48bd-87c1-cea7d78ac5af/ HTTP/1.1" 200 99
"GET / HTTP/1.1" 200 610
"GET /d9c78467-1948-4082-b1cc-2f7a693b40db/ HTTP/1.1" 200 208
Watching for file changes with StatReloader
Watching for file changes with StatReloader
"GET /d9c78467-1948-4082-b1cc-2f7a693b40db/ HTTP/1.1" 200 436
"GET / HTTP/1.1" 200 838
Watching for file changes with StatReloader
/Users/malenkijkotik/Desktop/progs/rsoi-online-store/online-store-orders/orders_app/urls.py changed, reloading.
Watching for file changes with StatReloader
Internal Server Error: /
Traceback (most recent call last):
  File "/Users/malenkijkotik/Desktop/progs/rsoi/env/lib/python3.7/site-packages/django/core/handlers/exception.py", line 34, in inner
    response = get_response(request)
  File "/Users/malenkijkotik/Desktop/progs/rsoi/env/lib/python3.7/site-packages/django/core/handlers/base.py", line 115, in _get_response
    response = self.process_exception_by_middleware(e, request)
  File "/Users/malenkijkotik/Desktop/progs/rsoi/env/lib/python3.7/site-packages/django/core/handlers/base.py", line 113, in _get_response
    response = wrapped_callback(request, *callback_args, **callback_kwargs)
  File "/Users/malenkijkotik/Desktop/progs/rsoi/env/lib/python3.7/site-packages/django/views/decorators/csrf.py", line 54, in wrapped_view
    return view_func(*args, **kwargs)
  File "/Users/malenkijkotik/Desktop/progs/rsoi/env/lib/python3.7/site-packages/django/views/generic/base.py", line 71, in view
    return self.dispatch(request, *args, **kwargs)
  File "/Users/malenkijkotik/Desktop/progs/rsoi/env/lib/python3.7/site-packages/rest_framework/views.py", line 497, in dispatch
    response = self.handle_exception(exc)
  File "/Users/malenkijkotik/Desktop/progs/rsoi/env/lib/python3.7/site-packages/rest_framework/views.py", line 457, in handle_exception
    self.raise_uncaught_exception(exc)
  File "/Users/malenkijkotik/Desktop/progs/rsoi/env/lib/python3.7/site-packages/rest_framework/views.py", line 468, in raise_uncaught_exception
    raise exc
  File "/Users/malenkijkotik/Desktop/progs/rsoi/env/lib/python3.7/site-packages/rest_framework/views.py", line 494, in dispatch
    response = handler(request, *args, **kwargs)
  File "/Users/malenkijkotik/Desktop/progs/rsoi-online-store/online-store-orders/orders_app/views.py", line 35, in get
    order['billing'] = billing_response[0].json()
  File "/Users/malenkijkotik/Desktop/progs/rsoi/env/lib/python3.7/site-packages/requests/models.py", line 897, in json
    return complexjson.loads(self.text, **kwargs)
  File "/Library/Frameworks/Python.framework/Versions/3.7/lib/python3.7/json/__init__.py", line 348, in loads
    return _default_decoder.decode(s)
  File "/Library/Frameworks/Python.framework/Versions/3.7/lib/python3.7/json/decoder.py", line 337, in decode
    obj, end = self.raw_decode(s, idx=_w(s, 0).end())
  File "/Library/Frameworks/Python.framework/Versions/3.7/lib/python3.7/json/decoder.py", line 355, in raw_decode
    raise JSONDecodeError("Expecting value", s, err.value) from None
json.decoder.JSONDecodeError: Expecting value: line 1 column 1 (char 0)
"GET / HTTP/1.1" 500 16107
/Users/malenkijkotik/Desktop/progs/rsoi-online-store/online-store-orders/orders_app/urls.py changed, reloading.
Watching for file changes with StatReloader
Internal Server Error: /
Traceback (most recent call last):
  File "/Users/malenkijkotik/Desktop/progs/rsoi/env/lib/python3.7/site-packages/django/core/handlers/exception.py", line 34, in inner
    response = get_response(request)
  File "/Users/malenkijkotik/Desktop/progs/rsoi/env/lib/python3.7/site-packages/django/core/handlers/base.py", line 115, in _get_response
    response = self.process_exception_by_middleware(e, request)
  File "/Users/malenkijkotik/Desktop/progs/rsoi/env/lib/python3.7/site-packages/django/core/handlers/base.py", line 113, in _get_response
    response = wrapped_callback(request, *callback_args, **callback_kwargs)
  File "/Users/malenkijkotik/Desktop/progs/rsoi/env/lib/python3.7/site-packages/django/views/decorators/csrf.py", line 54, in wrapped_view
    return view_func(*args, **kwargs)
  File "/Users/malenkijkotik/Desktop/progs/rsoi/env/lib/python3.7/site-packages/django/views/generic/base.py", line 71, in view
    return self.dispatch(request, *args, **kwargs)
  File "/Users/malenkijkotik/Desktop/progs/rsoi/env/lib/python3.7/site-packages/rest_framework/views.py", line 497, in dispatch
    response = self.handle_exception(exc)
  File "/Users/malenkijkotik/Desktop/progs/rsoi/env/lib/python3.7/site-packages/rest_framework/views.py", line 457, in handle_exception
    self.raise_uncaught_exception(exc)
  File "/Users/malenkijkotik/Desktop/progs/rsoi/env/lib/python3.7/site-packages/rest_framework/views.py", line 468, in raise_uncaught_exception
    raise exc
  File "/Users/malenkijkotik/Desktop/progs/rsoi/env/lib/python3.7/site-packages/rest_framework/views.py", line 494, in dispatch
    response = handler(request, *args, **kwargs)
  File "/Users/malenkijkotik/Desktop/progs/rsoi-online-store/online-store-orders/orders_app/views.py", line 35, in get
    order['billing'] = billing_response[0].json()
  File "/Users/malenkijkotik/Desktop/progs/rsoi/env/lib/python3.7/site-packages/requests/models.py", line 897, in json
    return complexjson.loads(self.text, **kwargs)
  File "/Library/Frameworks/Python.framework/Versions/3.7/lib/python3.7/json/__init__.py", line 348, in loads
    return _default_decoder.decode(s)
  File "/Library/Frameworks/Python.framework/Versions/3.7/lib/python3.7/json/decoder.py", line 337, in decode
    obj, end = self.raw_decode(s, idx=_w(s, 0).end())
  File "/Library/Frameworks/Python.framework/Versions/3.7/lib/python3.7/json/decoder.py", line 355, in raw_decode
    raise JSONDecodeError("Expecting value", s, err.value) from None
json.decoder.JSONDecodeError: Expecting value: line 1 column 1 (char 0)
"GET / HTTP/1.1" 500 16107
/Users/malenkijkotik/Desktop/progs/rsoi-online-store/online-store-orders/orders_app/views.py changed, reloading.
Watching for file changes with StatReloader
Internal Server Error: /
Traceback (most recent call last):
  File "/Users/malenkijkotik/Desktop/progs/rsoi/env/lib/python3.7/site-packages/django/core/handlers/exception.py", line 34, in inner
    response = get_response(request)
  File "/Users/malenkijkotik/Desktop/progs/rsoi/env/lib/python3.7/site-packages/django/core/handlers/base.py", line 115, in _get_response
    response = self.process_exception_by_middleware(e, request)
  File "/Users/malenkijkotik/Desktop/progs/rsoi/env/lib/python3.7/site-packages/django/core/handlers/base.py", line 113, in _get_response
    response = wrapped_callback(request, *callback_args, **callback_kwargs)
  File "/Users/malenkijkotik/Desktop/progs/rsoi/env/lib/python3.7/site-packages/django/views/decorators/csrf.py", line 54, in wrapped_view
    return view_func(*args, **kwargs)
  File "/Users/malenkijkotik/Desktop/progs/rsoi/env/lib/python3.7/site-packages/django/views/generic/base.py", line 71, in view
    return self.dispatch(request, *args, **kwargs)
  File "/Users/malenkijkotik/Desktop/progs/rsoi/env/lib/python3.7/site-packages/rest_framework/views.py", line 497, in dispatch
    response = self.handle_exception(exc)
  File "/Users/malenkijkotik/Desktop/progs/rsoi/env/lib/python3.7/site-packages/rest_framework/views.py", line 457, in handle_exception
    self.raise_uncaught_exception(exc)
  File "/Users/malenkijkotik/Desktop/progs/rsoi/env/lib/python3.7/site-packages/rest_framework/views.py", line 468, in raise_uncaught_exception
    raise exc
  File "/Users/malenkijkotik/Desktop/progs/rsoi/env/lib/python3.7/site-packages/rest_framework/views.py", line 494, in dispatch
    response = handler(request, *args, **kwargs)
  File "/Users/malenkijkotik/Desktop/progs/rsoi-online-store/online-store-orders/orders_app/views.py", line 36, in get
    order['billing'] = billing_response[0].json()
  File "/Users/malenkijkotik/Desktop/progs/rsoi/env/lib/python3.7/site-packages/requests/models.py", line 897, in json
    return complexjson.loads(self.text, **kwargs)
  File "/Library/Frameworks/Python.framework/Versions/3.7/lib/python3.7/json/__init__.py", line 348, in loads
    return _default_decoder.decode(s)
  File "/Library/Frameworks/Python.framework/Versions/3.7/lib/python3.7/json/decoder.py", line 337, in decode
    obj, end = self.raw_decode(s, idx=_w(s, 0).end())
  File "/Library/Frameworks/Python.framework/Versions/3.7/lib/python3.7/json/decoder.py", line 355, in raw_decode
    raise JSONDecodeError("Expecting value", s, err.value) from None
json.decoder.JSONDecodeError: Expecting value: line 1 column 1 (char 0)
"GET / HTTP/1.1" 500 16107
/Users/malenkijkotik/Desktop/progs/rsoi-online-store/online-store-orders/orders_app/views.py changed, reloading.
Watching for file changes with StatReloader
Internal Server Error: /
Traceback (most recent call last):
  File "/Users/malenkijkotik/Desktop/progs/rsoi/env/lib/python3.7/site-packages/django/core/handlers/exception.py", line 34, in inner
    response = get_response(request)
  File "/Users/malenkijkotik/Desktop/progs/rsoi/env/lib/python3.7/site-packages/django/core/handlers/base.py", line 115, in _get_response
    response = self.process_exception_by_middleware(e, request)
  File "/Users/malenkijkotik/Desktop/progs/rsoi/env/lib/python3.7/site-packages/django/core/handlers/base.py", line 113, in _get_response
    response = wrapped_callback(request, *callback_args, **callback_kwargs)
  File "/Users/malenkijkotik/Desktop/progs/rsoi/env/lib/python3.7/site-packages/django/views/decorators/csrf.py", line 54, in wrapped_view
    return view_func(*args, **kwargs)
  File "/Users/malenkijkotik/Desktop/progs/rsoi/env/lib/python3.7/site-packages/django/views/generic/base.py", line 71, in view
    return self.dispatch(request, *args, **kwargs)
  File "/Users/malenkijkotik/Desktop/progs/rsoi/env/lib/python3.7/site-packages/rest_framework/views.py", line 497, in dispatch
    response = self.handle_exception(exc)
  File "/Users/malenkijkotik/Desktop/progs/rsoi/env/lib/python3.7/site-packages/rest_framework/views.py", line 457, in handle_exception
    self.raise_uncaught_exception(exc)
  File "/Users/malenkijkotik/Desktop/progs/rsoi/env/lib/python3.7/site-packages/rest_framework/views.py", line 468, in raise_uncaught_exception
    raise exc
  File "/Users/malenkijkotik/Desktop/progs/rsoi/env/lib/python3.7/site-packages/rest_framework/views.py", line 494, in dispatch
    response = handler(request, *args, **kwargs)
  File "/Users/malenkijkotik/Desktop/progs/rsoi-online-store/online-store-orders/orders_app/views.py", line 37, in get
    order['billing'] = billing_response[0].json()
  File "/Users/malenkijkotik/Desktop/progs/rsoi/env/lib/python3.7/site-packages/requests/models.py", line 897, in json
    return complexjson.loads(self.text, **kwargs)
  File "/Library/Frameworks/Python.framework/Versions/3.7/lib/python3.7/json/__init__.py", line 348, in loads
    return _default_decoder.decode(s)
  File "/Library/Frameworks/Python.framework/Versions/3.7/lib/python3.7/json/decoder.py", line 337, in decode
    obj, end = self.raw_decode(s, idx=_w(s, 0).end())
  File "/Library/Frameworks/Python.framework/Versions/3.7/lib/python3.7/json/decoder.py", line 355, in raw_decode
    raise JSONDecodeError("Expecting value", s, err.value) from None
json.decoder.JSONDecodeError: Expecting value: line 1 column 1 (char 0)
"GET / HTTP/1.1" 500 16107
/Users/malenkijkotik/Desktop/progs/rsoi-online-store/online-store-orders/orders_app/requesters/billing_requester.py changed, reloading.
Watching for file changes with StatReloader
/Users/malenkijkotik/Desktop/progs/rsoi-online-store/online-store-orders/orders_app/requesters/items_requester.py changed, reloading.
Watching for file changes with StatReloader
"GET / HTTP/1.1" 200 838
"GET /orders_short/ HTTP/1.1" 200 610
"GET / HTTP/1.1" 200 838
"GET /orders_short/ HTTP/1.1" 200 610
"GET /orders_short/d9c78467-1948-4082-b1cc-2f7a693b40db/ HTTP/1.1" 200 436
/Users/malenkijkotik/Desktop/progs/rsoi-online-store/online-store-orders/orders_app/views.py changed, reloading.
Watching for file changes with StatReloader
/Users/malenkijkotik/Desktop/progs/rsoi-online-store/online-store-orders/orders_app/views.py changed, reloading.
Watching for file changes with StatReloader
Internal Server Error: /orders_short/d9c78467-1948-4082-b1cc-2f7a693b40db/
Traceback (most recent call last):
  File "/Users/malenkijkotik/Desktop/progs/rsoi/env/lib/python3.7/site-packages/django/core/handlers/exception.py", line 34, in inner
    response = get_response(request)
  File "/Users/malenkijkotik/Desktop/progs/rsoi/env/lib/python3.7/site-packages/django/core/handlers/base.py", line 115, in _get_response
    response = self.process_exception_by_middleware(e, request)
  File "/Users/malenkijkotik/Desktop/progs/rsoi/env/lib/python3.7/site-packages/django/core/handlers/base.py", line 113, in _get_response
    response = wrapped_callback(request, *callback_args, **callback_kwargs)
  File "/Users/malenkijkotik/Desktop/progs/rsoi/env/lib/python3.7/site-packages/django/views/decorators/csrf.py", line 54, in wrapped_view
    return view_func(*args, **kwargs)
  File "/Users/malenkijkotik/Desktop/progs/rsoi/env/lib/python3.7/site-packages/django/views/generic/base.py", line 71, in view
    return self.dispatch(request, *args, **kwargs)
  File "/Users/malenkijkotik/Desktop/progs/rsoi/env/lib/python3.7/site-packages/rest_framework/views.py", line 497, in dispatch
    response = self.handle_exception(exc)
  File "/Users/malenkijkotik/Desktop/progs/rsoi/env/lib/python3.7/site-packages/rest_framework/views.py", line 457, in handle_exception
    self.raise_uncaught_exception(exc)
  File "/Users/malenkijkotik/Desktop/progs/rsoi/env/lib/python3.7/site-packages/rest_framework/views.py", line 468, in raise_uncaught_exception
    raise exc
  File "/Users/malenkijkotik/Desktop/progs/rsoi/env/lib/python3.7/site-packages/rest_framework/views.py", line 494, in dispatch
    response = handler(request, *args, **kwargs)
  File "/Users/malenkijkotik/Desktop/progs/rsoi-online-store/online-store-orders/orders_app/views.py", line 128, in get
    return Response(serialized, status=status.HTTP_200_OK)
  File "/Users/malenkijkotik/Desktop/progs/rsoi/env/lib/python3.7/site-packages/rest_framework/response.py", line 38, in __init__
    raise AssertionError(msg)
AssertionError: You passed a Serializer instance as data, but probably meant to pass serialized `.data` or `.error`. representation.
"GET /orders_short/d9c78467-1948-4082-b1cc-2f7a693b40db/ HTTP/1.1" 500 15724
/Users/malenkijkotik/Desktop/progs/rsoi-online-store/online-store-orders/orders_app/views.py changed, reloading.
Watching for file changes with StatReloader
"GET /orders_short/d9c78467-1948-4082-b1cc-2f7a693b40db/ HTTP/1.1" 200 208
/Users/malenkijkotik/Desktop/progs/rsoi-online-store/online-store-orders/orders_app/views.py changed, reloading.
Watching for file changes with StatReloader
/Users/malenkijkotik/Desktop/progs/rsoi-online-store/online-store-orders/orders_app/requesters/items_requester.py changed, reloading.
Watching for file changes with StatReloader
Watching for file changes with StatReloader
/Users/malenkijkotik/Desktop/progs/rsoi-online-store/online-store-orders/orders_app/requesters/billing_requester.py changed, reloading.
Watching for file changes with StatReloader
Internal Server Error: /
"POST / HTTP/1.1" 500 0
Internal Server Error: /
Traceback (most recent call last):
  File "/Users/malenkijkotik/Desktop/progs/rsoi/env/lib/python3.7/site-packages/django/core/handlers/exception.py", line 34, in inner
    response = get_response(request)
  File "/Users/malenkijkotik/Desktop/progs/rsoi/env/lib/python3.7/site-packages/django/core/handlers/base.py", line 115, in _get_response
    response = self.process_exception_by_middleware(e, request)
  File "/Users/malenkijkotik/Desktop/progs/rsoi/env/lib/python3.7/site-packages/django/core/handlers/base.py", line 113, in _get_response
    response = wrapped_callback(request, *callback_args, **callback_kwargs)
  File "/Users/malenkijkotik/Desktop/progs/rsoi/env/lib/python3.7/site-packages/django/views/decorators/csrf.py", line 54, in wrapped_view
    return view_func(*args, **kwargs)
  File "/Users/malenkijkotik/Desktop/progs/rsoi/env/lib/python3.7/site-packages/django/views/generic/base.py", line 71, in view
    return self.dispatch(request, *args, **kwargs)
  File "/Users/malenkijkotik/Desktop/progs/rsoi/env/lib/python3.7/site-packages/rest_framework/views.py", line 497, in dispatch
    response = self.handle_exception(exc)
  File "/Users/malenkijkotik/Desktop/progs/rsoi/env/lib/python3.7/site-packages/rest_framework/views.py", line 457, in handle_exception
    self.raise_uncaught_exception(exc)
  File "/Users/malenkijkotik/Desktop/progs/rsoi/env/lib/python3.7/site-packages/rest_framework/views.py", line 468, in raise_uncaught_exception
    raise exc
  File "/Users/malenkijkotik/Desktop/progs/rsoi/env/lib/python3.7/site-packages/rest_framework/views.py", line 494, in dispatch
    response = handler(request, *args, **kwargs)
  File "/Users/malenkijkotik/Desktop/progs/rsoi-online-store/online-store-orders/orders_app/views.py", line 54, in post
    serializer = OrderSerializer(data=data, billing=billing_uuid)
  File "/Users/malenkijkotik/Desktop/progs/rsoi/env/lib/python3.7/site-packages/rest_framework/serializers.py", line 117, in __init__
    super().__init__(**kwargs)
TypeError: __init__() got an unexpected keyword argument 'billing'
"POST / HTTP/1.1" 500 15441
/Users/malenkijkotik/Desktop/progs/rsoi-online-store/online-store-orders/orders_app/views.py changed, reloading.
Watching for file changes with StatReloader
/Users/malenkijkotik/Desktop/progs/rsoi-online-store/online-store-orders/orders_app/views.py changed, reloading.
Watching for file changes with StatReloader
Internal Server Error: /
Traceback (most recent call last):
  File "/Users/malenkijkotik/Desktop/progs/rsoi/env/lib/python3.7/site-packages/django/core/handlers/exception.py", line 34, in inner
    response = get_response(request)
  File "/Users/malenkijkotik/Desktop/progs/rsoi/env/lib/python3.7/site-packages/django/core/handlers/base.py", line 115, in _get_response
    response = self.process_exception_by_middleware(e, request)
  File "/Users/malenkijkotik/Desktop/progs/rsoi/env/lib/python3.7/site-packages/django/core/handlers/base.py", line 113, in _get_response
    response = wrapped_callback(request, *callback_args, **callback_kwargs)
  File "/Users/malenkijkotik/Desktop/progs/rsoi/env/lib/python3.7/site-packages/django/views/decorators/csrf.py", line 54, in wrapped_view
    return view_func(*args, **kwargs)
  File "/Users/malenkijkotik/Desktop/progs/rsoi/env/lib/python3.7/site-packages/django/views/generic/base.py", line 71, in view
    return self.dispatch(request, *args, **kwargs)
  File "/Users/malenkijkotik/Desktop/progs/rsoi/env/lib/python3.7/site-packages/rest_framework/views.py", line 497, in dispatch
    response = self.handle_exception(exc)
  File "/Users/malenkijkotik/Desktop/progs/rsoi/env/lib/python3.7/site-packages/rest_framework/views.py", line 457, in handle_exception
    self.raise_uncaught_exception(exc)
  File "/Users/malenkijkotik/Desktop/progs/rsoi/env/lib/python3.7/site-packages/rest_framework/views.py", line 468, in raise_uncaught_exception
    raise exc
  File "/Users/malenkijkotik/Desktop/progs/rsoi/env/lib/python3.7/site-packages/rest_framework/views.py", line 494, in dispatch
    response = handler(request, *args, **kwargs)
  File "/Users/malenkijkotik/Desktop/progs/rsoi-online-store/online-store-orders/orders_app/views.py", line 54, in post
    serializer = OrderSerializer(isClosed=data.isClosed, itemsInOrder=data.itemsInOrder, billing=billing_uuid)
AttributeError: 'QueryDict' object has no attribute 'isClosed'
"POST / HTTP/1.1" 500 15314
/Users/malenkijkotik/Desktop/progs/rsoi-online-store/online-store-orders/orders_app/views.py changed, reloading.
Watching for file changes with StatReloader
/Users/malenkijkotik/Desktop/progs/rsoi-online-store/online-store-orders/orders_app/views.py changed, reloading.
Watching for file changes with StatReloader
Internal Server Error: /
Traceback (most recent call last):
  File "/Users/malenkijkotik/Desktop/progs/rsoi-online-store/online-store-orders/orders_app/requesters/requester.py", line 48, in get_data_from_response
    return response.json()
AttributeError: 'QueryDict' object has no attribute 'json'

During handling of the above exception, another exception occurred:

Traceback (most recent call last):
  File "/Users/malenkijkotik/Desktop/progs/rsoi/env/lib/python3.7/site-packages/django/core/handlers/exception.py", line 34, in inner
    response = get_response(request)
  File "/Users/malenkijkotik/Desktop/progs/rsoi/env/lib/python3.7/site-packages/django/core/handlers/base.py", line 115, in _get_response
    response = self.process_exception_by_middleware(e, request)
  File "/Users/malenkijkotik/Desktop/progs/rsoi/env/lib/python3.7/site-packages/django/core/handlers/base.py", line 113, in _get_response
    response = wrapped_callback(request, *callback_args, **callback_kwargs)
  File "/Users/malenkijkotik/Desktop/progs/rsoi/env/lib/python3.7/site-packages/django/views/decorators/csrf.py", line 54, in wrapped_view
    return view_func(*args, **kwargs)
  File "/Users/malenkijkotik/Desktop/progs/rsoi/env/lib/python3.7/site-packages/django/views/generic/base.py", line 71, in view
    return self.dispatch(request, *args, **kwargs)
  File "/Users/malenkijkotik/Desktop/progs/rsoi/env/lib/python3.7/site-packages/rest_framework/views.py", line 497, in dispatch
    response = self.handle_exception(exc)
  File "/Users/malenkijkotik/Desktop/progs/rsoi/env/lib/python3.7/site-packages/rest_framework/views.py", line 457, in handle_exception
    self.raise_uncaught_exception(exc)
  File "/Users/malenkijkotik/Desktop/progs/rsoi/env/lib/python3.7/site-packages/rest_framework/views.py", line 468, in raise_uncaught_exception
    raise exc
  File "/Users/malenkijkotik/Desktop/progs/rsoi/env/lib/python3.7/site-packages/rest_framework/views.py", line 494, in dispatch
    response = handler(request, *args, **kwargs)
  File "/Users/malenkijkotik/Desktop/progs/rsoi-online-store/online-store-orders/orders_app/views.py", line 49, in post
    data = self.BILLING_REQUESTER.get_data_from_response(data)
  File "/Users/malenkijkotik/Desktop/progs/rsoi-online-store/online-store-orders/orders_app/requesters/requester.py", line 50, in get_data_from_response
    return response.text
AttributeError: 'QueryDict' object has no attribute 'text'
"POST / HTTP/1.1" 500 15718
/Users/malenkijkotik/Desktop/progs/rsoi-online-store/online-store-orders/orders_app/views.py changed, reloading.
Watching for file changes with StatReloader
Internal Server Error: /
Traceback (most recent call last):
  File "/Users/malenkijkotik/Desktop/progs/rsoi/env/lib/python3.7/site-packages/django/core/handlers/exception.py", line 34, in inner
    response = get_response(request)
  File "/Users/malenkijkotik/Desktop/progs/rsoi/env/lib/python3.7/site-packages/django/core/handlers/base.py", line 115, in _get_response
    response = self.process_exception_by_middleware(e, request)
  File "/Users/malenkijkotik/Desktop/progs/rsoi/env/lib/python3.7/site-packages/django/core/handlers/base.py", line 113, in _get_response
    response = wrapped_callback(request, *callback_args, **callback_kwargs)
  File "/Users/malenkijkotik/Desktop/progs/rsoi/env/lib/python3.7/site-packages/django/views/decorators/csrf.py", line 54, in wrapped_view
    return view_func(*args, **kwargs)
  File "/Users/malenkijkotik/Desktop/progs/rsoi/env/lib/python3.7/site-packages/django/views/generic/base.py", line 71, in view
    return self.dispatch(request, *args, **kwargs)
  File "/Users/malenkijkotik/Desktop/progs/rsoi/env/lib/python3.7/site-packages/rest_framework/views.py", line 497, in dispatch
    response = self.handle_exception(exc)
  File "/Users/malenkijkotik/Desktop/progs/rsoi/env/lib/python3.7/site-packages/rest_framework/views.py", line 457, in handle_exception
    self.raise_uncaught_exception(exc)
  File "/Users/malenkijkotik/Desktop/progs/rsoi/env/lib/python3.7/site-packages/rest_framework/views.py", line 468, in raise_uncaught_exception
    raise exc
  File "/Users/malenkijkotik/Desktop/progs/rsoi/env/lib/python3.7/site-packages/rest_framework/views.py", line 494, in dispatch
    response = handler(request, *args, **kwargs)
  File "/Users/malenkijkotik/Desktop/progs/rsoi-online-store/online-store-orders/orders_app/views.py", line 54, in post
    serializer = OrderSerializer(billing=billing_uuid)
  File "/Users/malenkijkotik/Desktop/progs/rsoi/env/lib/python3.7/site-packages/rest_framework/serializers.py", line 117, in __init__
    super().__init__(**kwargs)
TypeError: __init__() got an unexpected keyword argument 'billing'
"POST / HTTP/1.1" 500 15430
/Users/malenkijkotik/Desktop/progs/rsoi-online-store/online-store-orders/orders_app/views.py changed, reloading.
Watching for file changes with StatReloader
/Users/malenkijkotik/Desktop/progs/rsoi-online-store/online-store-orders/orders_app/views.py changed, reloading.
Watching for file changes with StatReloader
Internal Server Error: /
Traceback (most recent call last):
  File "/Users/malenkijkotik/Desktop/progs/rsoi/env/lib/python3.7/site-packages/django/core/handlers/exception.py", line 34, in inner
    response = get_response(request)
  File "/Users/malenkijkotik/Desktop/progs/rsoi/env/lib/python3.7/site-packages/django/core/handlers/base.py", line 115, in _get_response
    response = self.process_exception_by_middleware(e, request)
  File "/Users/malenkijkotik/Desktop/progs/rsoi/env/lib/python3.7/site-packages/django/core/handlers/base.py", line 113, in _get_response
    response = wrapped_callback(request, *callback_args, **callback_kwargs)
  File "/Users/malenkijkotik/Desktop/progs/rsoi/env/lib/python3.7/site-packages/django/views/decorators/csrf.py", line 54, in wrapped_view
    return view_func(*args, **kwargs)
  File "/Users/malenkijkotik/Desktop/progs/rsoi/env/lib/python3.7/site-packages/django/views/generic/base.py", line 71, in view
    return self.dispatch(request, *args, **kwargs)
  File "/Users/malenkijkotik/Desktop/progs/rsoi/env/lib/python3.7/site-packages/rest_framework/views.py", line 497, in dispatch
    response = self.handle_exception(exc)
  File "/Users/malenkijkotik/Desktop/progs/rsoi/env/lib/python3.7/site-packages/rest_framework/views.py", line 457, in handle_exception
    self.raise_uncaught_exception(exc)
  File "/Users/malenkijkotik/Desktop/progs/rsoi/env/lib/python3.7/site-packages/rest_framework/views.py", line 468, in raise_uncaught_exception
    raise exc
  File "/Users/malenkijkotik/Desktop/progs/rsoi/env/lib/python3.7/site-packages/rest_framework/views.py", line 494, in dispatch
    response = handler(request, *args, **kwargs)
  File "/Users/malenkijkotik/Desktop/progs/rsoi-online-store/online-store-orders/orders_app/views.py", line 56, in post
    if serializer.is_valid():
AttributeError: 'ReturnDict' object has no attribute 'is_valid'
"POST / HTTP/1.1" 500 15235
/Users/malenkijkotik/Desktop/progs/rsoi-online-store/online-store-orders/orders_app/views.py changed, reloading.
Watching for file changes with StatReloader
Internal Server Error: /
Traceback (most recent call last):
  File "/Users/malenkijkotik/Desktop/progs/rsoi/env/lib/python3.7/site-packages/django/core/handlers/exception.py", line 34, in inner
    response = get_response(request)
  File "/Users/malenkijkotik/Desktop/progs/rsoi/env/lib/python3.7/site-packages/django/core/handlers/base.py", line 115, in _get_response
    response = self.process_exception_by_middleware(e, request)
  File "/Users/malenkijkotik/Desktop/progs/rsoi/env/lib/python3.7/site-packages/django/core/handlers/base.py", line 113, in _get_response
    response = wrapped_callback(request, *callback_args, **callback_kwargs)
  File "/Users/malenkijkotik/Desktop/progs/rsoi/env/lib/python3.7/site-packages/django/views/decorators/csrf.py", line 54, in wrapped_view
    return view_func(*args, **kwargs)
  File "/Users/malenkijkotik/Desktop/progs/rsoi/env/lib/python3.7/site-packages/django/views/generic/base.py", line 71, in view
    return self.dispatch(request, *args, **kwargs)
  File "/Users/malenkijkotik/Desktop/progs/rsoi/env/lib/python3.7/site-packages/rest_framework/views.py", line 497, in dispatch
    response = self.handle_exception(exc)
  File "/Users/malenkijkotik/Desktop/progs/rsoi/env/lib/python3.7/site-packages/rest_framework/views.py", line 457, in handle_exception
    self.raise_uncaught_exception(exc)
  File "/Users/malenkijkotik/Desktop/progs/rsoi/env/lib/python3.7/site-packages/rest_framework/views.py", line 468, in raise_uncaught_exception
    raise exc
  File "/Users/malenkijkotik/Desktop/progs/rsoi/env/lib/python3.7/site-packages/rest_framework/views.py", line 494, in dispatch
    response = handler(request, *args, **kwargs)
  File "/Users/malenkijkotik/Desktop/progs/rsoi-online-store/online-store-orders/orders_app/views.py", line 56, in post
    serializer.save()
AttributeError: 'ReturnDict' object has no attribute 'save'
"POST / HTTP/1.1" 500 15219
/Users/malenkijkotik/Desktop/progs/rsoi-online-store/online-store-orders/orders_app/views.py changed, reloading.
Watching for file changes with StatReloader
"POST / HTTP/1.1" 201 133
"POST / HTTP/1.1" 201 133
"POST / HTTP/1.1" 201 133
Watching for file changes with StatReloader
"POST / HTTP/1.1" 201 133
"POST / HTTP/1.1" 201 133
"POST / HTTP/1.1" 201 133
/Users/malenkijkotik/Desktop/progs/rsoi-online-store/online-store-orders/orders_app/views.py changed, reloading.
Watching for file changes with StatReloader
/Users/malenkijkotik/Desktop/progs/rsoi-online-store/online-store-orders/orders_app/views.py changed, reloading.
Watching for file changes with StatReloader
/Users/malenkijkotik/Desktop/progs/rsoi-online-store/online-store-orders/orders_app/views.py changed, reloading.
Watching for file changes with StatReloader
/Users/malenkijkotik/Desktop/progs/rsoi-online-store/online-store-orders/orders_app/views.py changed, reloading.
Watching for file changes with StatReloader
/Users/malenkijkotik/Desktop/progs/rsoi-online-store/online-store-orders/orders_app/views.py changed, reloading.
Watching for file changes with StatReloader
/Users/malenkijkotik/Desktop/progs/rsoi-online-store/online-store-orders/orders_app/views.py changed, reloading.
Watching for file changes with StatReloader
Watching for file changes with StatReloader
Unsupported Media Type: /
"POST / HTTP/1.1" 415 0
Internal Server Error: /
Traceback (most recent call last):
  File "/Users/malenkijkotik/Desktop/progs/rsoi/env/lib/python3.7/site-packages/django/core/handlers/exception.py", line 34, in inner
    response = get_response(request)
  File "/Users/malenkijkotik/Desktop/progs/rsoi/env/lib/python3.7/site-packages/django/core/handlers/base.py", line 115, in _get_response
    response = self.process_exception_by_middleware(e, request)
  File "/Users/malenkijkotik/Desktop/progs/rsoi/env/lib/python3.7/site-packages/django/core/handlers/base.py", line 113, in _get_response
    response = wrapped_callback(request, *callback_args, **callback_kwargs)
  File "/Users/malenkijkotik/Desktop/progs/rsoi/env/lib/python3.7/site-packages/django/views/decorators/csrf.py", line 54, in wrapped_view
    return view_func(*args, **kwargs)
  File "/Users/malenkijkotik/Desktop/progs/rsoi/env/lib/python3.7/site-packages/django/views/generic/base.py", line 71, in view
    return self.dispatch(request, *args, **kwargs)
  File "/Users/malenkijkotik/Desktop/progs/rsoi/env/lib/python3.7/site-packages/rest_framework/views.py", line 497, in dispatch
    response = self.handle_exception(exc)
  File "/Users/malenkijkotik/Desktop/progs/rsoi/env/lib/python3.7/site-packages/rest_framework/views.py", line 457, in handle_exception
    self.raise_uncaught_exception(exc)
  File "/Users/malenkijkotik/Desktop/progs/rsoi/env/lib/python3.7/site-packages/rest_framework/views.py", line 468, in raise_uncaught_exception
    raise exc
  File "/Users/malenkijkotik/Desktop/progs/rsoi/env/lib/python3.7/site-packages/rest_framework/views.py", line 494, in dispatch
    response = handler(request, *args, **kwargs)
  File "/Users/malenkijkotik/Desktop/progs/rsoi-online-store/online-store-orders/orders_app/views.py", line 37, in get
    order['billing'] = billing_response[0].json()
  File "/Users/malenkijkotik/Desktop/progs/rsoi/env/lib/python3.7/site-packages/requests/models.py", line 897, in json
    return complexjson.loads(self.text, **kwargs)
  File "/Library/Frameworks/Python.framework/Versions/3.7/lib/python3.7/json/__init__.py", line 348, in loads
    return _default_decoder.decode(s)
  File "/Library/Frameworks/Python.framework/Versions/3.7/lib/python3.7/json/decoder.py", line 337, in decode
    obj, end = self.raw_decode(s, idx=_w(s, 0).end())
  File "/Library/Frameworks/Python.framework/Versions/3.7/lib/python3.7/json/decoder.py", line 355, in raw_decode
    raise JSONDecodeError("Expecting value", s, err.value) from None
json.decoder.JSONDecodeError: Expecting value: line 1 column 1 (char 0)
"GET / HTTP/1.1" 500 114263
Not Found: /favicon.ico
"GET /favicon.ico HTTP/1.1" 404 2778
/Users/malenkijkotik/Desktop/progs/rsoi-online-store/online-store-orders/orders_app/requesters/billing_requester.py changed, reloading.
Watching for file changes with StatReloader
"POST / HTTP/1.1" 201 133
Watching for file changes with StatReloader
"GET /a4448f4b-b24b-45bc-b9f2-4119b2ba9236 HTTP/1.1" 301 0
"GET /a4448f4b-b24b-45bc-b9f2-4119b2ba9236/ HTTP/1.1" 200 2022
Internal Server Error: /
Traceback (most recent call last):
  File "/Users/malenkijkotik/Desktop/progs/rsoi/env/lib/python3.7/site-packages/django/core/handlers/exception.py", line 34, in inner
    response = get_response(request)
  File "/Users/malenkijkotik/Desktop/progs/rsoi/env/lib/python3.7/site-packages/django/core/handlers/base.py", line 115, in _get_response
    response = self.process_exception_by_middleware(e, request)
  File "/Users/malenkijkotik/Desktop/progs/rsoi/env/lib/python3.7/site-packages/django/core/handlers/base.py", line 113, in _get_response
    response = wrapped_callback(request, *callback_args, **callback_kwargs)
  File "/Users/malenkijkotik/Desktop/progs/rsoi/env/lib/python3.7/site-packages/django/views/decorators/csrf.py", line 54, in wrapped_view
    return view_func(*args, **kwargs)
  File "/Users/malenkijkotik/Desktop/progs/rsoi/env/lib/python3.7/site-packages/django/views/generic/base.py", line 71, in view
    return self.dispatch(request, *args, **kwargs)
  File "/Users/malenkijkotik/Desktop/progs/rsoi/env/lib/python3.7/site-packages/rest_framework/views.py", line 497, in dispatch
    response = self.handle_exception(exc)
  File "/Users/malenkijkotik/Desktop/progs/rsoi/env/lib/python3.7/site-packages/rest_framework/views.py", line 457, in handle_exception
    self.raise_uncaught_exception(exc)
  File "/Users/malenkijkotik/Desktop/progs/rsoi/env/lib/python3.7/site-packages/rest_framework/views.py", line 468, in raise_uncaught_exception
    raise exc
  File "/Users/malenkijkotik/Desktop/progs/rsoi/env/lib/python3.7/site-packages/rest_framework/views.py", line 494, in dispatch
    response = handler(request, *args, **kwargs)
  File "/Users/malenkijkotik/Desktop/progs/rsoi-online-store/online-store-orders/orders_app/views.py", line 42, in get
    order['itemsInOrder'][i] = item_response[0].json()
  File "/Users/malenkijkotik/Desktop/progs/rsoi/env/lib/python3.7/site-packages/requests/models.py", line 897, in json
    return complexjson.loads(self.text, **kwargs)
  File "/Library/Frameworks/Python.framework/Versions/3.7/lib/python3.7/json/__init__.py", line 348, in loads
    return _default_decoder.decode(s)
  File "/Library/Frameworks/Python.framework/Versions/3.7/lib/python3.7/json/decoder.py", line 337, in decode
    obj, end = self.raw_decode(s, idx=_w(s, 0).end())
  File "/Library/Frameworks/Python.framework/Versions/3.7/lib/python3.7/json/decoder.py", line 355, in raw_decode
    raise JSONDecodeError("Expecting value", s, err.value) from None
json.decoder.JSONDecodeError: Expecting value: line 1 column 1 (char 0)
"GET / HTTP/1.1" 500 16050
Internal Server Error: /
Traceback (most recent call last):
  File "/Users/malenkijkotik/Desktop/progs/rsoi/env/lib/python3.7/site-packages/django/core/handlers/exception.py", line 34, in inner
    response = get_response(request)
  File "/Users/malenkijkotik/Desktop/progs/rsoi/env/lib/python3.7/site-packages/django/core/handlers/base.py", line 115, in _get_response
    response = self.process_exception_by_middleware(e, request)
  File "/Users/malenkijkotik/Desktop/progs/rsoi/env/lib/python3.7/site-packages/django/core/handlers/base.py", line 113, in _get_response
    response = wrapped_callback(request, *callback_args, **callback_kwargs)
  File "/Users/malenkijkotik/Desktop/progs/rsoi/env/lib/python3.7/site-packages/django/views/decorators/csrf.py", line 54, in wrapped_view
    return view_func(*args, **kwargs)
  File "/Users/malenkijkotik/Desktop/progs/rsoi/env/lib/python3.7/site-packages/django/views/generic/base.py", line 71, in view
    return self.dispatch(request, *args, **kwargs)
  File "/Users/malenkijkotik/Desktop/progs/rsoi/env/lib/python3.7/site-packages/rest_framework/views.py", line 497, in dispatch
    response = self.handle_exception(exc)
  File "/Users/malenkijkotik/Desktop/progs/rsoi/env/lib/python3.7/site-packages/rest_framework/views.py", line 457, in handle_exception
    self.raise_uncaught_exception(exc)
  File "/Users/malenkijkotik/Desktop/progs/rsoi/env/lib/python3.7/site-packages/rest_framework/views.py", line 468, in raise_uncaught_exception
    raise exc
  File "/Users/malenkijkotik/Desktop/progs/rsoi/env/lib/python3.7/site-packages/rest_framework/views.py", line 494, in dispatch
    response = handler(request, *args, **kwargs)
  File "/Users/malenkijkotik/Desktop/progs/rsoi-online-store/online-store-orders/orders_app/views.py", line 42, in get
    order['itemsInOrder'][i] = item_response[0].json()
  File "/Users/malenkijkotik/Desktop/progs/rsoi/env/lib/python3.7/site-packages/requests/models.py", line 897, in json
    return complexjson.loads(self.text, **kwargs)
  File "/Library/Frameworks/Python.framework/Versions/3.7/lib/python3.7/json/__init__.py", line 348, in loads
    return _default_decoder.decode(s)
  File "/Library/Frameworks/Python.framework/Versions/3.7/lib/python3.7/json/decoder.py", line 337, in decode
    obj, end = self.raw_decode(s, idx=_w(s, 0).end())
  File "/Library/Frameworks/Python.framework/Versions/3.7/lib/python3.7/json/decoder.py", line 355, in raw_decode
    raise JSONDecodeError("Expecting value", s, err.value) from None
json.decoder.JSONDecodeError: Expecting value: line 1 column 1 (char 0)
"GET / HTTP/1.1" 500 16050
/Users/malenkijkotik/Desktop/progs/rsoi-online-store/online-store-orders/orders_app/views.py changed, reloading.
Watching for file changes with StatReloader
/Users/malenkijkotik/Desktop/progs/rsoi-online-store/online-store-orders/orders_app/views.py changed, reloading.
Watching for file changes with StatReloader
Internal Server Error: /
Traceback (most recent call last):
  File "/Users/malenkijkotik/Desktop/progs/rsoi/env/lib/python3.7/site-packages/django/core/handlers/exception.py", line 34, in inner
    response = get_response(request)
  File "/Users/malenkijkotik/Desktop/progs/rsoi/env/lib/python3.7/site-packages/django/core/handlers/base.py", line 115, in _get_response
    response = self.process_exception_by_middleware(e, request)
  File "/Users/malenkijkotik/Desktop/progs/rsoi/env/lib/python3.7/site-packages/django/core/handlers/base.py", line 113, in _get_response
    response = wrapped_callback(request, *callback_args, **callback_kwargs)
  File "/Users/malenkijkotik/Desktop/progs/rsoi/env/lib/python3.7/site-packages/django/views/decorators/csrf.py", line 54, in wrapped_view
    return view_func(*args, **kwargs)
  File "/Users/malenkijkotik/Desktop/progs/rsoi/env/lib/python3.7/site-packages/django/views/generic/base.py", line 71, in view
    return self.dispatch(request, *args, **kwargs)
  File "/Users/malenkijkotik/Desktop/progs/rsoi/env/lib/python3.7/site-packages/rest_framework/views.py", line 497, in dispatch
    response = self.handle_exception(exc)
  File "/Users/malenkijkotik/Desktop/progs/rsoi/env/lib/python3.7/site-packages/rest_framework/views.py", line 457, in handle_exception
    self.raise_uncaught_exception(exc)
  File "/Users/malenkijkotik/Desktop/progs/rsoi/env/lib/python3.7/site-packages/rest_framework/views.py", line 468, in raise_uncaught_exception
    raise exc
  File "/Users/malenkijkotik/Desktop/progs/rsoi/env/lib/python3.7/site-packages/rest_framework/views.py", line 494, in dispatch
    response = handler(request, *args, **kwargs)
  File "/Users/malenkijkotik/Desktop/progs/rsoi-online-store/online-store-orders/orders_app/views.py", line 37, in get
    order['billing'] = billing_response[0].json()
TypeError: 'Response' object does not support indexing
"GET / HTTP/1.1" 500 15141
/Users/malenkijkotik/Desktop/progs/rsoi-online-store/online-store-orders/orders_app/views.py changed, reloading.
Watching for file changes with StatReloader
/Users/malenkijkotik/Desktop/progs/rsoi-online-store/online-store-orders/orders_app/views.py changed, reloading.
Watching for file changes with StatReloader
/Users/malenkijkotik/Desktop/progs/rsoi-online-store/online-store-orders/orders_app/views.py changed, reloading.
Watching for file changes with StatReloader
Internal Server Error: /
Traceback (most recent call last):
  File "/Users/malenkijkotik/Desktop/progs/rsoi/env/lib/python3.7/site-packages/django/core/handlers/exception.py", line 34, in inner
    response = get_response(request)
  File "/Users/malenkijkotik/Desktop/progs/rsoi/env/lib/python3.7/site-packages/django/core/handlers/base.py", line 115, in _get_response
    response = self.process_exception_by_middleware(e, request)
  File "/Users/malenkijkotik/Desktop/progs/rsoi/env/lib/python3.7/site-packages/django/core/handlers/base.py", line 113, in _get_response
    response = wrapped_callback(request, *callback_args, **callback_kwargs)
  File "/Users/malenkijkotik/Desktop/progs/rsoi/env/lib/python3.7/site-packages/django/views/decorators/csrf.py", line 54, in wrapped_view
    return view_func(*args, **kwargs)
  File "/Users/malenkijkotik/Desktop/progs/rsoi/env/lib/python3.7/site-packages/django/views/generic/base.py", line 71, in view
    return self.dispatch(request, *args, **kwargs)
  File "/Users/malenkijkotik/Desktop/progs/rsoi/env/lib/python3.7/site-packages/rest_framework/views.py", line 497, in dispatch
    response = self.handle_exception(exc)
  File "/Users/malenkijkotik/Desktop/progs/rsoi/env/lib/python3.7/site-packages/rest_framework/views.py", line 457, in handle_exception
    self.raise_uncaught_exception(exc)
  File "/Users/malenkijkotik/Desktop/progs/rsoi/env/lib/python3.7/site-packages/rest_framework/views.py", line 468, in raise_uncaught_exception
    raise exc
  File "/Users/malenkijkotik/Desktop/progs/rsoi/env/lib/python3.7/site-packages/rest_framework/views.py", line 494, in dispatch
    response = handler(request, *args, **kwargs)
  File "/Users/malenkijkotik/Desktop/progs/rsoi-online-store/online-store-orders/orders_app/views.py", line 38, in get
    order['billing'] = billing_data[0].json()
AttributeError: 'dict' object has no attribute 'json'
"GET / HTTP/1.1" 500 15135
/Users/malenkijkotik/Desktop/progs/rsoi-online-store/online-store-orders/orders_app/views.py changed, reloading.
Watching for file changes with StatReloader
"GET / HTTP/1.1" 200 2496
/Users/malenkijkotik/Desktop/progs/rsoi-online-store/online-store-orders/orders_app/views.py changed, reloading.
Watching for file changes with StatReloader
"GET /0152bdde-a2bb-48bd-87c1-cea7d78ac5af/ HTTP/1.1" 200 99
/Users/malenkijkotik/Desktop/progs/rsoi-online-store/online-store-orders/orders_app/views.py changed, reloading.
Watching for file changes with StatReloader
"GET /0152bdde-a2bb-48bd-87c1-cea7d78ac5af/ HTTP/1.1" 200 99
"GET / HTTP/1.1" 200 2496
Watching for file changes with StatReloader
Unauthorized: /
"GET / HTTP/1.1" 401 183
"GET / HTTP/1.1" 200 2496
"POST / HTTP/1.1" 201 133
Watching for file changes with StatReloader
"GET / HTTP/1.1" 200 2698
/Users/malenkijkotik/Desktop/progs/rsoi-online-store/online-store-orders/orders_app/views.py changed, reloading.
Watching for file changes with StatReloader
"GET / HTTP/1.1" 200 27437
/Users/malenkijkotik/Desktop/progs/rsoi-online-store/online-store-orders/orders_app/views.py changed, reloading.
Watching for file changes with StatReloader
"GET / HTTP/1.1" 200 2698
/Users/malenkijkotik/Desktop/progs/rsoi-online-store/online-store-orders/orders_app/views.py changed, reloading.
Watching for file changes with StatReloader
"GET / HTTP/1.1" 200 2698
/Users/malenkijkotik/Desktop/progs/rsoi-online-store/online-store-orders/orders_app/requesters/billing_requester.py changed, reloading.
Watching for file changes with StatReloader
Internal Server Error: /
Traceback (most recent call last):
  File "/Users/malenkijkotik/Desktop/progs/rsoi/env/lib/python3.7/site-packages/django/core/handlers/exception.py", line 34, in inner
    response = get_response(request)
  File "/Users/malenkijkotik/Desktop/progs/rsoi/env/lib/python3.7/site-packages/django/core/handlers/base.py", line 115, in _get_response
    response = self.process_exception_by_middleware(e, request)
  File "/Users/malenkijkotik/Desktop/progs/rsoi/env/lib/python3.7/site-packages/django/core/handlers/base.py", line 113, in _get_response
    response = wrapped_callback(request, *callback_args, **callback_kwargs)
  File "/Users/malenkijkotik/Desktop/progs/rsoi/env/lib/python3.7/site-packages/django/views/decorators/csrf.py", line 54, in wrapped_view
    return view_func(*args, **kwargs)
  File "/Users/malenkijkotik/Desktop/progs/rsoi/env/lib/python3.7/site-packages/django/views/generic/base.py", line 71, in view
    return self.dispatch(request, *args, **kwargs)
  File "/Users/malenkijkotik/Desktop/progs/rsoi/env/lib/python3.7/site-packages/rest_framework/views.py", line 497, in dispatch
    response = self.handle_exception(exc)
  File "/Users/malenkijkotik/Desktop/progs/rsoi/env/lib/python3.7/site-packages/rest_framework/views.py", line 457, in handle_exception
    self.raise_uncaught_exception(exc)
  File "/Users/malenkijkotik/Desktop/progs/rsoi/env/lib/python3.7/site-packages/rest_framework/views.py", line 468, in raise_uncaught_exception
    raise exc
  File "/Users/malenkijkotik/Desktop/progs/rsoi/env/lib/python3.7/site-packages/rest_framework/views.py", line 494, in dispatch
    response = handler(request, *args, **kwargs)
  File "/Users/malenkijkotik/Desktop/progs/rsoi-online-store/online-store-orders/orders_app/views.py", line 39, in get
    order['billing'] = billing_data[0]
KeyError: 0
"GET / HTTP/1.1" 500 15101
/Users/malenkijkotik/Desktop/progs/rsoi-online-store/online-store-orders/orders_app/views.py changed, reloading.
Watching for file changes with StatReloader
"GET / HTTP/1.1" 200 2562
/Users/malenkijkotik/Desktop/progs/rsoi-online-store/online-store-orders/orders_app/views.py changed, reloading.
Watching for file changes with StatReloader
Watching for file changes with StatReloader
"GET / HTTP/1.1" 200 2790
"GET / HTTP/1.1" 200 2790
"GET / HTTP/1.1" 200 2790
Watching for file changes with StatReloader
"POST / HTTP/1.1" 201 133
"GET / HTTP/1.1" 200 31172
/Users/malenkijkotik/Desktop/progs/rsoi-online-store/online-store-orders/orders_app/views.py changed, reloading.
Watching for file changes with StatReloader
"GET / HTTP/1.1" 200 31172
/Users/malenkijkotik/Desktop/progs/rsoi-online-store/online-store-orders/orders_app/requesters/billing_requester.py changed, reloading.
Watching for file changes with StatReloader
"GET / HTTP/1.1" 200 31172
/Users/malenkijkotik/Desktop/progs/rsoi-online-store/online-store-orders/orders_app/requesters/billing_requester.py changed, reloading.
Watching for file changes with StatReloader
"GET / HTTP/1.1" 200 2696
/Users/malenkijkotik/Desktop/progs/rsoi-online-store/online-store-orders/orders_app/requesters/billing_requester.py changed, reloading.
Watching for file changes with StatReloader
/Users/malenkijkotik/Desktop/progs/rsoi-online-store/online-store-orders/orders_app/requesters/billing_requester.py changed, reloading.
Watching for file changes with StatReloader
/Users/malenkijkotik/Desktop/progs/rsoi-online-store/online-store-orders/orders_app/requesters/items_requester.py changed, reloading.
Watching for file changes with StatReloader
"GET /a4448f4b-b24b-45bc-b9f2-4119b2ba9236/ HTTP/1.1" 200 133
"GET /a4448f4b-b24b-45bc-b9f2-4119b2ba9236/ HTTP/1.1" 200 133
"GET /8cd43516-b9ac-464e-91cf-042701518402/ HTTP/1.1" 200 133
Internal Server Error: /
"POST / HTTP/1.1" 500 0
"POST / HTTP/1.1" 201 133
"POST / HTTP/1.1" 201 133
"POST / HTTP/1.1" 201 133
"POST / HTTP/1.1" 201 133
"POST / HTTP/1.1" 201 133
"POST / HTTP/1.1" 201 133
"POST / HTTP/1.1" 201 133
"POST / HTTP/1.1" 201 133
"POST / HTTP/1.1" 201 133
"POST / HTTP/1.1" 201 133
"POST / HTTP/1.1" 201 133
"POST / HTTP/1.1" 201 133
"POST / HTTP/1.1" 201 133
"GET /a4448f4b-b24b-45bc-b9f2-4119b2ba9236/ HTTP/1.1" 200 201
"GET /f241607c-e6c2-42e6-9811-7dfe6dbc440a/ HTTP/1.1" 200 201
"GET /dc120eb3-8bc9-4f58-9bbc-c2f3db2b34db/ HTTP/1.1" 200 201
"GET /42f261c7-1086-4536-bb63-cf9cdb7d06f5/ HTTP/1.1" 200 201
"GET /48299ce6-7c73-4ea6-af5c-8773ab9cd44d/ HTTP/1.1" 200 201
"GET /840cfec0-eefa-4dd7-904a-8ddc29bf4845/ HTTP/1.1" 200 201
"GET /4226214d-2402-421d-a344-67899cf7f364/ HTTP/1.1" 200 201
"GET /6b676fbd-d498-4958-814f-b3544ee1d687/ HTTP/1.1" 200 201
"GET /ceb6048f-0657-4ad2-89cc-d65a086f91ae/ HTTP/1.1" 200 201
"GET /8cd43516-b9ac-464e-91cf-042701518402/ HTTP/1.1" 200 201
"GET /a4448f4b-b24b-45bc-b9f2-4119b2ba9236/ HTTP/1.1" 200 201
"GET /f241607c-e6c2-42e6-9811-7dfe6dbc440a/ HTTP/1.1" 200 201
"GET /dc120eb3-8bc9-4f58-9bbc-c2f3db2b34db/ HTTP/1.1" 200 201
"GET /42f261c7-1086-4536-bb63-cf9cdb7d06f5/ HTTP/1.1" 200 201
"GET /48299ce6-7c73-4ea6-af5c-8773ab9cd44d/ HTTP/1.1" 200 201
"GET /840cfec0-eefa-4dd7-904a-8ddc29bf4845/ HTTP/1.1" 200 201
"GET /4226214d-2402-421d-a344-67899cf7f364/ HTTP/1.1" 200 201
"GET /6b676fbd-d498-4958-814f-b3544ee1d687/ HTTP/1.1" 200 201
"GET /ceb6048f-0657-4ad2-89cc-d65a086f91ae/ HTTP/1.1" 200 201
"POST / HTTP/1.1" 201 133
"POST / HTTP/1.1" 201 133
"POST / HTTP/1.1" 201 133
/Users/malenkijkotik/Desktop/progs/rsoi-online-store/online-store-orders/orders_app/requesters/billing_requester.py changed, reloading.
Watching for file changes with StatReloader
/Users/malenkijkotik/Desktop/progs/rsoi-online-store/online-store-orders/orders_app/requesters/billing_requester.py changed, reloading.
Watching for file changes with StatReloader
"POST / HTTP/1.1" 201 133
/Users/malenkijkotik/Desktop/progs/rsoi-online-store/online-store-orders/orders_app/requesters/billing_requester.py changed, reloading.
Watching for file changes with StatReloader
Watching for file changes with StatReloader
"GET /orders_short/ HTTP/1.1" 200 4362
Internal Server Error: /orders_short/0152bdde-a2bb-48bd-87c1-cea7d78ac5af/
Traceback (most recent call last):
  File "/Users/malenkijkotik/Desktop/progs/rsoi/env/lib/python3.7/site-packages/django/core/handlers/exception.py", line 34, in inner
    response = get_response(request)
  File "/Users/malenkijkotik/Desktop/progs/rsoi/env/lib/python3.7/site-packages/django/core/handlers/base.py", line 115, in _get_response
    response = self.process_exception_by_middleware(e, request)
  File "/Users/malenkijkotik/Desktop/progs/rsoi/env/lib/python3.7/site-packages/django/core/handlers/base.py", line 113, in _get_response
    response = wrapped_callback(request, *callback_args, **callback_kwargs)
  File "/Users/malenkijkotik/Desktop/progs/rsoi/env/lib/python3.7/site-packages/django/views/decorators/csrf.py", line 54, in wrapped_view
    return view_func(*args, **kwargs)
  File "/Users/malenkijkotik/Desktop/progs/rsoi/env/lib/python3.7/site-packages/django/views/generic/base.py", line 71, in view
    return self.dispatch(request, *args, **kwargs)
  File "/Users/malenkijkotik/Desktop/progs/rsoi/env/lib/python3.7/site-packages/rest_framework/views.py", line 497, in dispatch
    response = self.handle_exception(exc)
  File "/Users/malenkijkotik/Desktop/progs/rsoi/env/lib/python3.7/site-packages/rest_framework/views.py", line 457, in handle_exception
    self.raise_uncaught_exception(exc)
  File "/Users/malenkijkotik/Desktop/progs/rsoi/env/lib/python3.7/site-packages/rest_framework/views.py", line 468, in raise_uncaught_exception
    raise exc
  File "/Users/malenkijkotik/Desktop/progs/rsoi/env/lib/python3.7/site-packages/rest_framework/views.py", line 485, in dispatch
    self.initial(request, *args, **kwargs)
  File "/Users/malenkijkotik/Desktop/progs/rsoi/env/lib/python3.7/site-packages/rest_framework/views.py", line 403, in initial
    self.check_permissions(request)
  File "/Users/malenkijkotik/Desktop/progs/rsoi/env/lib/python3.7/site-packages/rest_framework/views.py", line 332, in check_permissions
    if not permission.has_permission(request, self):
  File "/Users/malenkijkotik/Desktop/progs/rsoi-online-store/online-store-orders/orders_app/permissions.py", line 31, in has_permission
    return int(view.kwargs[view.lookup_url_kwarg]) == auth_json['id'] or auth_json['is_superuser']
AttributeError: 'OrderWithoutDetail' object has no attribute 'lookup_url_kwarg'
"PATCH /orders_short/0152bdde-a2bb-48bd-87c1-cea7d78ac5af/ HTTP/1.1" 500 15583
/Users/malenkijkotik/Desktop/progs/rsoi-online-store/online-store-orders/orders_app/views.py changed, reloading.
Watching for file changes with StatReloader
Forbidden: /orders_short/0152bdde-a2bb-48bd-87c1-cea7d78ac5af/
"PATCH /orders_short/0152bdde-a2bb-48bd-87c1-cea7d78ac5af/ HTTP/1.1" 403 58
Forbidden: /orders_short/0152bdde-a2bb-48bd-87c1-cea7d78ac5af/
"PATCH /orders_short/0152bdde-a2bb-48bd-87c1-cea7d78ac5af/ HTTP/1.1" 403 58
Forbidden: /orders_short/0152bdde-a2bb-48bd-87c1-cea7d78ac5af/
"PATCH /orders_short/0152bdde-a2bb-48bd-87c1-cea7d78ac5af/ HTTP/1.1" 403 58
Not Found: /orders_short/70e3a47e-16c7-45dc-8308-47248c0c5acf/
"GET /orders_short/70e3a47e-16c7-45dc-8308-47248c0c5acf/ HTTP/1.1" 404 0
/Users/malenkijkotik/Desktop/progs/rsoi-online-store/online-store-orders/orders_app/views.py changed, reloading.
Watching for file changes with StatReloader
/Users/malenkijkotik/Desktop/progs/rsoi-online-store/online-store-orders/orders_app/views.py changed, reloading.
Watching for file changes with StatReloader
/Users/malenkijkotik/Desktop/progs/rsoi-online-store/online-store-orders/orders_app/views.py changed, reloading.
Watching for file changes with StatReloader
Internal Server Error: /orders_short/70e3a47e-16c7-45dc-8308-47248c0c5acf/
Traceback (most recent call last):
  File "/Users/malenkijkotik/Desktop/progs/rsoi/env/lib/python3.7/site-packages/django/core/handlers/exception.py", line 34, in inner
    response = get_response(request)
  File "/Users/malenkijkotik/Desktop/progs/rsoi/env/lib/python3.7/site-packages/django/core/handlers/base.py", line 115, in _get_response
    response = self.process_exception_by_middleware(e, request)
  File "/Users/malenkijkotik/Desktop/progs/rsoi/env/lib/python3.7/site-packages/django/core/handlers/base.py", line 113, in _get_response
    response = wrapped_callback(request, *callback_args, **callback_kwargs)
  File "/Users/malenkijkotik/Desktop/progs/rsoi/env/lib/python3.7/site-packages/django/views/decorators/csrf.py", line 54, in wrapped_view
    return view_func(*args, **kwargs)
  File "/Users/malenkijkotik/Desktop/progs/rsoi/env/lib/python3.7/site-packages/django/views/generic/base.py", line 71, in view
    return self.dispatch(request, *args, **kwargs)
  File "/Users/malenkijkotik/Desktop/progs/rsoi/env/lib/python3.7/site-packages/rest_framework/views.py", line 497, in dispatch
    response = self.handle_exception(exc)
  File "/Users/malenkijkotik/Desktop/progs/rsoi/env/lib/python3.7/site-packages/rest_framework/views.py", line 457, in handle_exception
    self.raise_uncaught_exception(exc)
  File "/Users/malenkijkotik/Desktop/progs/rsoi/env/lib/python3.7/site-packages/rest_framework/views.py", line 468, in raise_uncaught_exception
    raise exc
  File "/Users/malenkijkotik/Desktop/progs/rsoi/env/lib/python3.7/site-packages/rest_framework/views.py", line 485, in dispatch
    self.initial(request, *args, **kwargs)
  File "/Users/malenkijkotik/Desktop/progs/rsoi/env/lib/python3.7/site-packages/rest_framework/views.py", line 403, in initial
    self.check_permissions(request)
  File "/Users/malenkijkotik/Desktop/progs/rsoi/env/lib/python3.7/site-packages/rest_framework/views.py", line 332, in check_permissions
    if not permission.has_permission(request, self):
  File "/Users/malenkijkotik/Desktop/progs/rsoi-online-store/online-store-orders/orders_app/permissions.py", line 62, in has_permission
    return AuthRequester().is_token_valid(token)[1]
  File "/Users/malenkijkotik/Desktop/progs/rsoi-online-store/online-store-orders/orders_app/requesters/authrequester.py", line 61, in is_token_valid
    response = self.post_request('api-token-verify/', data={'token': token})
  File "/Users/malenkijkotik/Desktop/progs/rsoi-online-store/online-store-orders/orders_app/requesters/requester.py", line 19, in post_request
    response = requests.post(url=url, json=data, headers=headers)
  File "/Users/malenkijkotik/Desktop/progs/rsoi/env/lib/python3.7/site-packages/requests/api.py", line 116, in post
    return request('post', url, data=data, json=json, **kwargs)
  File "/Users/malenkijkotik/Desktop/progs/rsoi/env/lib/python3.7/site-packages/requests/api.py", line 60, in request
    return session.request(method=method, url=url, **kwargs)
  File "/Users/malenkijkotik/Desktop/progs/rsoi/env/lib/python3.7/site-packages/requests/sessions.py", line 519, in request
    prep = self.prepare_request(req)
  File "/Users/malenkijkotik/Desktop/progs/rsoi/env/lib/python3.7/site-packages/requests/sessions.py", line 462, in prepare_request
    hooks=merge_hooks(request.hooks, self.hooks),
  File "/Users/malenkijkotik/Desktop/progs/rsoi/env/lib/python3.7/site-packages/requests/models.py", line 313, in prepare
    self.prepare_url(url, params)
  File "/Users/malenkijkotik/Desktop/progs/rsoi/env/lib/python3.7/site-packages/requests/models.py", line 387, in prepare_url
    raise MissingSchema(error)
requests.exceptions.MissingSchema: Invalid URL 'api-token-verify/': No schema supplied. Perhaps you meant http://api-token-verify/?
"GET /orders_short/70e3a47e-16c7-45dc-8308-47248c0c5acf/ HTTP/1.1" 500 17300
/Users/malenkijkotik/Desktop/progs/rsoi-online-store/online-store-orders/orders_app/requesters/authrequester.py changed, reloading.
Watching for file changes with StatReloader
Not Found: /orders_short/70e3a47e-16c7-45dc-8308-47248c0c5acf/
"GET /orders_short/70e3a47e-16c7-45dc-8308-47248c0c5acf/ HTTP/1.1" 404 0
"GET /orders_short/ HTTP/1.1" 200 4362
"GET /orders_short/0152bdde-a2bb-48bd-87c1-cea7d78ac5af/ HTTP/1.1" 200 99
Watching for file changes with StatReloader
Forbidden: /
"GET / HTTP/1.1" 403 58
"GET / HTTP/1.1" 200 4566
"GET /0152bdde-a2bb-48bd-87c1-cea7d78ac5af/ HTTP/1.1" 200 99
"PATCH /0152bdde-a2bb-48bd-87c1-cea7d78ac5af/ HTTP/1.1" 202 99
"PATCH /0152bdde-a2bb-48bd-87c1-cea7d78ac5af/ HTTP/1.1" 202 99
"PATCH /0152bdde-a2bb-48bd-87c1-cea7d78ac5af/ HTTP/1.1" 202 99
/Users/malenkijkotik/Desktop/progs/rsoi-online-store/online-store-orders/orders_app/views.py changed, reloading.
Watching for file changes with StatReloader
/Users/malenkijkotik/Desktop/progs/rsoi-online-store/online-store-orders/orders_app/views.py changed, reloading.
Watching for file changes with StatReloader
Internal Server Error: /0152bdde-a2bb-48bd-87c1-cea7d78ac5af/
Traceback (most recent call last):
  File "/Users/malenkijkotik/Desktop/progs/rsoi/env/lib/python3.7/site-packages/django/core/handlers/exception.py", line 34, in inner
    response = get_response(request)
  File "/Users/malenkijkotik/Desktop/progs/rsoi/env/lib/python3.7/site-packages/django/core/handlers/base.py", line 115, in _get_response
    response = self.process_exception_by_middleware(e, request)
  File "/Users/malenkijkotik/Desktop/progs/rsoi/env/lib/python3.7/site-packages/django/core/handlers/base.py", line 113, in _get_response
    response = wrapped_callback(request, *callback_args, **callback_kwargs)
  File "/Users/malenkijkotik/Desktop/progs/rsoi/env/lib/python3.7/site-packages/django/views/decorators/csrf.py", line 54, in wrapped_view
    return view_func(*args, **kwargs)
  File "/Users/malenkijkotik/Desktop/progs/rsoi/env/lib/python3.7/site-packages/django/views/generic/base.py", line 71, in view
    return self.dispatch(request, *args, **kwargs)
  File "/Users/malenkijkotik/Desktop/progs/rsoi/env/lib/python3.7/site-packages/rest_framework/views.py", line 497, in dispatch
    response = self.handle_exception(exc)
  File "/Users/malenkijkotik/Desktop/progs/rsoi/env/lib/python3.7/site-packages/rest_framework/views.py", line 457, in handle_exception
    self.raise_uncaught_exception(exc)
  File "/Users/malenkijkotik/Desktop/progs/rsoi/env/lib/python3.7/site-packages/rest_framework/views.py", line 468, in raise_uncaught_exception
    raise exc
  File "/Users/malenkijkotik/Desktop/progs/rsoi/env/lib/python3.7/site-packages/rest_framework/views.py", line 494, in dispatch
    response = handler(request, *args, **kwargs)
  File "/Users/malenkijkotik/Desktop/progs/rsoi-online-store/online-store-orders/orders_app/views.py", line 130, in patch
    print(serializer.data)
  File "/Users/malenkijkotik/Desktop/progs/rsoi/env/lib/python3.7/site-packages/rest_framework/serializers.py", line 559, in data
    ret = super().data
  File "/Users/malenkijkotik/Desktop/progs/rsoi/env/lib/python3.7/site-packages/rest_framework/serializers.py", line 257, in data
    raise AssertionError(msg)
AssertionError: When a serializer is passed a `data` keyword argument you must call `.is_valid()` before attempting to access the serialized `.data` representation.
You should either call `.is_valid()` first, or access `.initial_data` instead.
"PATCH /0152bdde-a2bb-48bd-87c1-cea7d78ac5af/ HTTP/1.1" 500 16070
/Users/malenkijkotik/Desktop/progs/rsoi-online-store/online-store-orders/orders_app/views.py changed, reloading.
Watching for file changes with StatReloader
"PATCH /0152bdde-a2bb-48bd-87c1-cea7d78ac5af/ HTTP/1.1" 202 99
"PATCH /0152bdde-a2bb-48bd-87c1-cea7d78ac5af/ HTTP/1.1" 202 99
/Users/malenkijkotik/Desktop/progs/rsoi-online-store/online-store-orders/orders_app/views.py changed, reloading.
Watching for file changes with StatReloader
"PATCH /0152bdde-a2bb-48bd-87c1-cea7d78ac5af/ HTTP/1.1" 202 99
"PATCH /0152bdde-a2bb-48bd-87c1-cea7d78ac5af/ HTTP/1.1" 202 99
/Users/malenkijkotik/Desktop/progs/rsoi-online-store/online-store-orders/orders_app/serializers.py changed, reloading.
Watching for file changes with StatReloader
"PATCH /0152bdde-a2bb-48bd-87c1-cea7d78ac5af/ HTTP/1.1" 202 99
/Users/malenkijkotik/Desktop/progs/rsoi-online-store/online-store-orders/orders_app/views.py changed, reloading.
Watching for file changes with StatReloader
/Users/malenkijkotik/Desktop/progs/rsoi-online-store/online-store-orders/orders_app/views.py changed, reloading.
Watching for file changes with StatReloader
Internal Server Error: /0152bdde-a2bb-48bd-87c1-cea7d78ac5af/
Traceback (most recent call last):
  File "/Users/malenkijkotik/Desktop/progs/rsoi/env/lib/python3.7/site-packages/django/core/handlers/exception.py", line 34, in inner
    response = get_response(request)
  File "/Users/malenkijkotik/Desktop/progs/rsoi/env/lib/python3.7/site-packages/django/core/handlers/base.py", line 115, in _get_response
    response = self.process_exception_by_middleware(e, request)
  File "/Users/malenkijkotik/Desktop/progs/rsoi/env/lib/python3.7/site-packages/django/core/handlers/base.py", line 113, in _get_response
    response = wrapped_callback(request, *callback_args, **callback_kwargs)
  File "/Users/malenkijkotik/Desktop/progs/rsoi/env/lib/python3.7/site-packages/django/views/decorators/csrf.py", line 54, in wrapped_view
    return view_func(*args, **kwargs)
  File "/Users/malenkijkotik/Desktop/progs/rsoi/env/lib/python3.7/site-packages/django/views/generic/base.py", line 71, in view
    return self.dispatch(request, *args, **kwargs)
  File "/Users/malenkijkotik/Desktop/progs/rsoi/env/lib/python3.7/site-packages/rest_framework/views.py", line 497, in dispatch
    response = self.handle_exception(exc)
  File "/Users/malenkijkotik/Desktop/progs/rsoi/env/lib/python3.7/site-packages/rest_framework/views.py", line 457, in handle_exception
    self.raise_uncaught_exception(exc)
  File "/Users/malenkijkotik/Desktop/progs/rsoi/env/lib/python3.7/site-packages/rest_framework/views.py", line 468, in raise_uncaught_exception
    raise exc
  File "/Users/malenkijkotik/Desktop/progs/rsoi/env/lib/python3.7/site-packages/rest_framework/views.py", line 494, in dispatch
    response = handler(request, *args, **kwargs)
  File "/Users/malenkijkotik/Desktop/progs/rsoi-online-store/online-store-orders/orders_app/views.py", line 131, in patch
    serializer.update(validated_data=request.data)
TypeError: update() missing 1 required positional argument: 'instance'
"PATCH /0152bdde-a2bb-48bd-87c1-cea7d78ac5af/ HTTP/1.1" 500 15433
/Users/malenkijkotik/Desktop/progs/rsoi-online-store/online-store-orders/orders_app/views.py changed, reloading.
Watching for file changes with StatReloader
Internal Server Error: /0152bdde-a2bb-48bd-87c1-cea7d78ac5af/
Traceback (most recent call last):
  File "/Users/malenkijkotik/Desktop/progs/rsoi/env/lib/python3.7/site-packages/django/core/handlers/exception.py", line 34, in inner
    response = get_response(request)
  File "/Users/malenkijkotik/Desktop/progs/rsoi/env/lib/python3.7/site-packages/django/core/handlers/base.py", line 115, in _get_response
    response = self.process_exception_by_middleware(e, request)
  File "/Users/malenkijkotik/Desktop/progs/rsoi/env/lib/python3.7/site-packages/django/core/handlers/base.py", line 113, in _get_response
    response = wrapped_callback(request, *callback_args, **callback_kwargs)
  File "/Users/malenkijkotik/Desktop/progs/rsoi/env/lib/python3.7/site-packages/django/views/decorators/csrf.py", line 54, in wrapped_view
    return view_func(*args, **kwargs)
  File "/Users/malenkijkotik/Desktop/progs/rsoi/env/lib/python3.7/site-packages/django/views/generic/base.py", line 71, in view
    return self.dispatch(request, *args, **kwargs)
  File "/Users/malenkijkotik/Desktop/progs/rsoi/env/lib/python3.7/site-packages/rest_framework/views.py", line 497, in dispatch
    response = self.handle_exception(exc)
  File "/Users/malenkijkotik/Desktop/progs/rsoi/env/lib/python3.7/site-packages/rest_framework/views.py", line 457, in handle_exception
    self.raise_uncaught_exception(exc)
  File "/Users/malenkijkotik/Desktop/progs/rsoi/env/lib/python3.7/site-packages/rest_framework/views.py", line 468, in raise_uncaught_exception
    raise exc
  File "/Users/malenkijkotik/Desktop/progs/rsoi/env/lib/python3.7/site-packages/rest_framework/views.py", line 494, in dispatch
    response = handler(request, *args, **kwargs)
  File "/Users/malenkijkotik/Desktop/progs/rsoi-online-store/online-store-orders/orders_app/views.py", line 132, in patch
    serializer.save()
  File "/Users/malenkijkotik/Desktop/progs/rsoi/env/lib/python3.7/site-packages/rest_framework/serializers.py", line 179, in save
    'You must call `.is_valid()` before calling `.save()`.'
AssertionError: You must call `.is_valid()` before calling `.save()`.
"PATCH /0152bdde-a2bb-48bd-87c1-cea7d78ac5af/ HTTP/1.1" 500 15595
/Users/malenkijkotik/Desktop/progs/rsoi-online-store/online-store-orders/orders_app/views.py changed, reloading.
Watching for file changes with StatReloader
Internal Server Error: /0152bdde-a2bb-48bd-87c1-cea7d78ac5af/
Traceback (most recent call last):
  File "/Users/malenkijkotik/Desktop/progs/rsoi/env/lib/python3.7/site-packages/django/core/handlers/exception.py", line 34, in inner
    response = get_response(request)
  File "/Users/malenkijkotik/Desktop/progs/rsoi/env/lib/python3.7/site-packages/django/core/handlers/base.py", line 115, in _get_response
    response = self.process_exception_by_middleware(e, request)
  File "/Users/malenkijkotik/Desktop/progs/rsoi/env/lib/python3.7/site-packages/django/core/handlers/base.py", line 113, in _get_response
    response = wrapped_callback(request, *callback_args, **callback_kwargs)
  File "/Users/malenkijkotik/Desktop/progs/rsoi/env/lib/python3.7/site-packages/django/views/decorators/csrf.py", line 54, in wrapped_view
    return view_func(*args, **kwargs)
  File "/Users/malenkijkotik/Desktop/progs/rsoi/env/lib/python3.7/site-packages/django/views/generic/base.py", line 71, in view
    return self.dispatch(request, *args, **kwargs)
  File "/Users/malenkijkotik/Desktop/progs/rsoi/env/lib/python3.7/site-packages/rest_framework/views.py", line 497, in dispatch
    response = self.handle_exception(exc)
  File "/Users/malenkijkotik/Desktop/progs/rsoi/env/lib/python3.7/site-packages/rest_framework/views.py", line 457, in handle_exception
    self.raise_uncaught_exception(exc)
  File "/Users/malenkijkotik/Desktop/progs/rsoi/env/lib/python3.7/site-packages/rest_framework/views.py", line 468, in raise_uncaught_exception
    raise exc
  File "/Users/malenkijkotik/Desktop/progs/rsoi/env/lib/python3.7/site-packages/rest_framework/views.py", line 494, in dispatch
    response = handler(request, *args, **kwargs)
  File "/Users/malenkijkotik/Desktop/progs/rsoi-online-store/online-store-orders/orders_app/views.py", line 132, in patch
    if serializer.is_valid():
  File "/Users/malenkijkotik/Desktop/progs/rsoi/env/lib/python3.7/site-packages/rest_framework/serializers.py", line 229, in is_valid
    'Cannot call `.is_valid()` as no `data=` keyword argument was '
AssertionError: Cannot call `.is_valid()` as no `data=` keyword argument was passed when instantiating the serializer instance.
"PATCH /0152bdde-a2bb-48bd-87c1-cea7d78ac5af/ HTTP/1.1" 500 15731
/Users/malenkijkotik/Desktop/progs/rsoi-online-store/online-store-orders/orders_app/views.py changed, reloading.
Watching for file changes with StatReloader
Internal Server Error: /0152bdde-a2bb-48bd-87c1-cea7d78ac5af/
Traceback (most recent call last):
  File "/Users/malenkijkotik/Desktop/progs/rsoi/env/lib/python3.7/site-packages/django/core/handlers/exception.py", line 34, in inner
    response = get_response(request)
  File "/Users/malenkijkotik/Desktop/progs/rsoi/env/lib/python3.7/site-packages/django/core/handlers/base.py", line 115, in _get_response
    response = self.process_exception_by_middleware(e, request)
  File "/Users/malenkijkotik/Desktop/progs/rsoi/env/lib/python3.7/site-packages/django/core/handlers/base.py", line 113, in _get_response
    response = wrapped_callback(request, *callback_args, **callback_kwargs)
  File "/Users/malenkijkotik/Desktop/progs/rsoi/env/lib/python3.7/site-packages/django/views/decorators/csrf.py", line 54, in wrapped_view
    return view_func(*args, **kwargs)
  File "/Users/malenkijkotik/Desktop/progs/rsoi/env/lib/python3.7/site-packages/django/views/generic/base.py", line 71, in view
    return self.dispatch(request, *args, **kwargs)
  File "/Users/malenkijkotik/Desktop/progs/rsoi/env/lib/python3.7/site-packages/rest_framework/views.py", line 497, in dispatch
    response = self.handle_exception(exc)
  File "/Users/malenkijkotik/Desktop/progs/rsoi/env/lib/python3.7/site-packages/rest_framework/views.py", line 457, in handle_exception
    self.raise_uncaught_exception(exc)
  File "/Users/malenkijkotik/Desktop/progs/rsoi/env/lib/python3.7/site-packages/rest_framework/views.py", line 468, in raise_uncaught_exception
    raise exc
  File "/Users/malenkijkotik/Desktop/progs/rsoi/env/lib/python3.7/site-packages/rest_framework/views.py", line 494, in dispatch
    response = handler(request, *args, **kwargs)
  File "/Users/malenkijkotik/Desktop/progs/rsoi-online-store/online-store-orders/orders_app/views.py", line 132, in patch
    if serializer.is_valid():
  File "/Users/malenkijkotik/Desktop/progs/rsoi/env/lib/python3.7/site-packages/rest_framework/serializers.py", line 229, in is_valid
    'Cannot call `.is_valid()` as no `data=` keyword argument was '
AssertionError: Cannot call `.is_valid()` as no `data=` keyword argument was passed when instantiating the serializer instance.
"PATCH /0152bdde-a2bb-48bd-87c1-cea7d78ac5af/ HTTP/1.1" 500 15731
/Users/malenkijkotik/Desktop/progs/rsoi-online-store/online-store-orders/orders_app/views.py changed, reloading.
Watching for file changes with StatReloader
"PATCH /0152bdde-a2bb-48bd-87c1-cea7d78ac5af/ HTTP/1.1" 202 99
"PATCH /0152bdde-a2bb-48bd-87c1-cea7d78ac5af/ HTTP/1.1" 202 99
/Users/malenkijkotik/Desktop/progs/rsoi-online-store/online-store-orders/orders_app/views.py changed, reloading.
Watching for file changes with StatReloader
/Users/malenkijkotik/Desktop/progs/rsoi-online-store/online-store-orders/orders_app/views.py changed, reloading.
Watching for file changes with StatReloader
Internal Server Error: /0152bdde-a2bb-48bd-87c1-cea7d78ac5af/
Traceback (most recent call last):
  File "/Users/malenkijkotik/Desktop/progs/rsoi/env/lib/python3.7/site-packages/django/core/handlers/exception.py", line 34, in inner
    response = get_response(request)
  File "/Users/malenkijkotik/Desktop/progs/rsoi/env/lib/python3.7/site-packages/django/core/handlers/base.py", line 115, in _get_response
    response = self.process_exception_by_middleware(e, request)
  File "/Users/malenkijkotik/Desktop/progs/rsoi/env/lib/python3.7/site-packages/django/core/handlers/base.py", line 113, in _get_response
    response = wrapped_callback(request, *callback_args, **callback_kwargs)
  File "/Users/malenkijkotik/Desktop/progs/rsoi/env/lib/python3.7/site-packages/django/views/decorators/csrf.py", line 54, in wrapped_view
    return view_func(*args, **kwargs)
  File "/Users/malenkijkotik/Desktop/progs/rsoi/env/lib/python3.7/site-packages/django/views/generic/base.py", line 71, in view
    return self.dispatch(request, *args, **kwargs)
  File "/Users/malenkijkotik/Desktop/progs/rsoi/env/lib/python3.7/site-packages/rest_framework/views.py", line 497, in dispatch
    response = self.handle_exception(exc)
  File "/Users/malenkijkotik/Desktop/progs/rsoi/env/lib/python3.7/site-packages/rest_framework/views.py", line 457, in handle_exception
    self.raise_uncaught_exception(exc)
  File "/Users/malenkijkotik/Desktop/progs/rsoi/env/lib/python3.7/site-packages/rest_framework/views.py", line 468, in raise_uncaught_exception
    raise exc
  File "/Users/malenkijkotik/Desktop/progs/rsoi/env/lib/python3.7/site-packages/rest_framework/views.py", line 494, in dispatch
    response = handler(request, *args, **kwargs)
  File "/Users/malenkijkotik/Desktop/progs/rsoi-online-store/online-store-orders/orders_app/views.py", line 133, in patch
    if serializer.is_valid():
  File "/Users/malenkijkotik/Desktop/progs/rsoi/env/lib/python3.7/site-packages/rest_framework/serializers.py", line 229, in is_valid
    'Cannot call `.is_valid()` as no `data=` keyword argument was '
AssertionError: Cannot call `.is_valid()` as no `data=` keyword argument was passed when instantiating the serializer instance.
"PATCH /0152bdde-a2bb-48bd-87c1-cea7d78ac5af/ HTTP/1.1" 500 15731
/Users/malenkijkotik/Desktop/progs/rsoi-online-store/online-store-orders/orders_app/views.py changed, reloading.
Watching for file changes with StatReloader
Internal Server Error: /0152bdde-a2bb-48bd-87c1-cea7d78ac5af/
Traceback (most recent call last):
  File "/Users/malenkijkotik/Desktop/progs/rsoi/env/lib/python3.7/site-packages/django/core/handlers/exception.py", line 34, in inner
    response = get_response(request)
  File "/Users/malenkijkotik/Desktop/progs/rsoi/env/lib/python3.7/site-packages/django/core/handlers/base.py", line 145, in _get_response
    response = self.process_exception_by_middleware(e, request)
  File "/Users/malenkijkotik/Desktop/progs/rsoi/env/lib/python3.7/site-packages/django/core/handlers/base.py", line 143, in _get_response
    response = response.render()
  File "/Users/malenkijkotik/Desktop/progs/rsoi/env/lib/python3.7/site-packages/django/template/response.py", line 106, in render
    self.content = self.rendered_content
  File "/Users/malenkijkotik/Desktop/progs/rsoi/env/lib/python3.7/site-packages/rest_framework/response.py", line 70, in rendered_content
    ret = renderer.render(self.data, accepted_media_type, context)
  File "/Users/malenkijkotik/Desktop/progs/rsoi/env/lib/python3.7/site-packages/rest_framework/renderers.py", line 104, in render
    allow_nan=not self.strict, separators=separators
  File "/Users/malenkijkotik/Desktop/progs/rsoi/env/lib/python3.7/site-packages/rest_framework/utils/json.py", line 25, in dumps
    return json.dumps(*args, **kwargs)
  File "/Library/Frameworks/Python.framework/Versions/3.7/lib/python3.7/json/__init__.py", line 238, in dumps
    **kw).encode(obj)
  File "/Library/Frameworks/Python.framework/Versions/3.7/lib/python3.7/json/encoder.py", line 199, in encode
    chunks = self.iterencode(o, _one_shot=True)
  File "/Library/Frameworks/Python.framework/Versions/3.7/lib/python3.7/json/encoder.py", line 257, in iterencode
    return _iterencode(o, 0)
  File "/Users/malenkijkotik/Desktop/progs/rsoi/env/lib/python3.7/site-packages/rest_framework/utils/encoders.py", line 67, in default
    return super().default(obj)
  File "/Library/Frameworks/Python.framework/Versions/3.7/lib/python3.7/json/encoder.py", line 179, in default
    raise TypeError(f'Object of type {o.__class__.__name__} '
TypeError: Object of type Order is not JSON serializable
"PATCH /0152bdde-a2bb-48bd-87c1-cea7d78ac5af/ HTTP/1.1" 500 98113
/Users/malenkijkotik/Desktop/progs/rsoi-online-store/online-store-orders/orders_app/views.py changed, reloading.
Watching for file changes with StatReloader
"PATCH /0152bdde-a2bb-48bd-87c1-cea7d78ac5af/ HTTP/1.1" 202 99
"GET /0152bdde-a2bb-48bd-87c1-cea7d78ac5af/ HTTP/1.1" 200 99
/Users/malenkijkotik/Desktop/progs/rsoi-online-store/online-store-orders/orders_app/views.py changed, reloading.
Watching for file changes with StatReloader
/Users/malenkijkotik/Desktop/progs/rsoi-online-store/online-store-orders/orders_app/views.py changed, reloading.
Watching for file changes with StatReloader
"GET /0152bdde-a2bb-48bd-87c1-cea7d78ac5af/ HTTP/1.1" 200 99
Not Found: /0152bdde-a2bb-48bd-87c1-cea7d78ac5af/
"DELETE /0152bdde-a2bb-48bd-87c1-cea7d78ac5af/ HTTP/1.1" 404 0
"GET / HTTP/1.1" 200 4566
Watching for file changes with StatReloader
"GET / HTTP/1.1" 200 6130
Forbidden: /
"POST / HTTP/1.1" 403 58
"POST / HTTP/1.1" 201 133
